Workbook

Sheet INCENTIVE
C3: ="INCENTIVE DL THÁNG "& TEXT('DL 1'!A3,"MM/yyyy") -> INCENTIVE DL THÁNG 12/2024
C4: ="(Kỳ lương tháng " & TEXT(EDATE('DL 1'!A3,1),"MM/yyyy") &")" -> (Kỳ lương tháng 01/2025)
C6: NHẬP THÔNG TIN
C7: TARGET DL | D7: TARGET ED | E7: DOANH SỐ ED | F7: PR3 DL | G7: PR6 DL
C8: 300000000 | D8: 230000000 | E8: 130000000 | F8: 98 | G8: 98
C12: TỔNG INCENTIVE
C13: THƯỞNG ĐẠT TARGET | D13: THƯỞNG DS THEO HS RISK | E13: THƯỞNG BẢO HIỂM | F13: TỔNG THƯỞNG
C14: =Table3[THƯỞNG ĐẠT TARGET] -> 2340000 | D14: {=Table4[THƯỞNG DOANH SỐ THEO HỆ SỐ RISK]} -> 4589000 | E14: =SUM('DL 1'!I3:I253) -> 403000 | F14: {=(Table1[[#This Row],[THƯỞNG ĐẠT TARGET]]+Table1[[#This Row],[THƯỞNG DS THEO HS RISK]])*Table2[[Hệ Số Đạt Chỉ tiêu ]]+Table1[[#This Row],[THƯỞNG BẢO HIỂM]]} -> 5946200
C16: HỆ SỐ ĐẠT CHỈ TIÊU CT NGÀNH HÀNG CHÍNH VÀ TỔNG
C17: Hệ Số Đạt Chỉ tiêu
C18: =Data!$K$53 -> 0.8
C20: THƯỞNG ĐẠT CHỈ TIÊU
C21: TARGET Dl | D21: GIẢI NGÂN DL | E21: % GIẢI NGÂN | F21: MỨC THƯỞNG | G21: HỆ SỐ | H21: THƯỞNG ĐẠT TARGET
C22: =C8 -> 300000000 | D22: =SUM('DL 1'!$E$3:$E$377) -> 352000000 | E22: =IFERROR(Table3[[#This Row],[GIẢI NGÂN DL]]/Table3[[#This Row],[TARGET Dl]],0) -> 1.1733333 | F22: =_xlfn.IFNA(INDEX(Data!$H$15:$P$15,1,MATCH(Table3[[#This Row],[TARGET Dl]]/1000000,Data!$H$14:$P$14,1))*1000,0) -> 1800000 | G22: =INDEX(Data!$H$18:$M$18,1,MATCH(Table3[[#This Row],[% GIẢI NGÂN]],Data!$H$17:$M$17,1)) -> 1.3 | H22: =Table3[[#This Row],[MỨC THƯỞNG]]*Table3[[#This Row],[HỆ SỐ]] -> 2340000
C24: THƯỞNG DOANH SỐ THEO HỆ SỐ RỦI RO
C25: KÊNH | D25: THƯỞNG DOANH SỐ | E25: PR3 | F25: PR6 | G25: HỆ SỐ RISK | H25: THƯỞNG DOANH SỐ THEO HỆ SỐ RISK
C26: DL | D26: =SUM('DL 1'!$J$3:$J$274) -> 3530000 | E26: =F8 -> 98 | F26: =G8 -> 98 | G26: =Data!$K$40 -> 1.3 | H26: =Table4[[#This Row],[THƯỞNG DOANH SỐ ]]*Table4[[#This Row],[HỆ SỐ RISK]] -> 4589000

Sheet DL 1
A1: Column3 | B1: Column4 | C1: Column5 | D1: Column6 | E1: Column7 | F1: Column8 | G1: Column9 | H1: Column10 | I1: Column11 | J1: Column12
A2: NGÀY LÀM HD | B2: TÊN KHÁCH HÀNG | C2: SỐ HD | D2: KỲ HẠN | E2: KHOẢN VAY | F2: Bảo Hiểm ( Có=Y Không= N) | G2: MÃ SCHEME | I2: BẢO HIỂM | J2: Thưởng Doanh số | K2: Hệ Số (%)
A3: 45630 | B3: LÊ HÀ TRIỀU | C3: DL031137755 | D3: 9 | E3: 29000000 | F3: N | G3: B | I3: =CONVERT!B2 -> 0 | J3: =CONVERT!AM2 -> 203000 | K3: =CONVERT!AL2 -> 0.7
A4: 45631 | B4: LÊ HÀ TRIỀU | C4: DL031137756 | D4: 12 | E4: 10000000 | F4: Y | G4: A | I4: =CONVERT!B3 -> 10000 | J4: =CONVERT!AM3 -> 120000 | K4: =CONVERT!AL3 -> 1.2
A5: 45632 | B5: LÊ HÀ TRIỀU | C5: DL031137757 | D5: 36 | E5: 9000000 | F5: N | G5: B | I5: =CONVERT!B4 -> 0 | J5: =CONVERT!AM4 -> 126000 | K5: =CONVERT!AL4 -> 1.4
A6: 45633 | B6: LÊ HÀ TRIỀU | C6: DL031137758 | D6: 15 | E6: 29000000 | F6: Y | G6: A | I6: =CONVERT!B5 -> 36000 | J6: =CONVERT!AM5 -> 435000 | K6: =CONVERT!AL5 -> 1.5
A7: 45634 | B7: LÊ HÀ TRIỀU | C7: DL031137759 | D7: 15 | E7: 29000000 | F7: Y | G7: C | I7: =CONVERT!B6 -> 31000 | J7: =CONVERT!AM6 -> 87000 | K7: =CONVERT!AL6 -> 0.3
A8: 45635 | B8: LÊ HÀ TRIỀU | C8: DL031137760 | D8: 12 | E8: 29000000 | F8: Y | G8: A | I8: =CONVERT!B7 -> 26000 | J8: =CONVERT!AM7 -> 348000 | K8: =CONVERT!AL7 -> 1.2
A9: 45636 | B9: LÊ HÀ TRIỀU | C9: DL031137761 | D9: 9 | E9: 9000000 | F9: Y | G9: C | I9: =CONVERT!B8 -> 10000 | J9: =CONVERT!AM8 -> 0 | K9: =CONVERT!AL8 -> 0
A10: 45637 | B10: LÊ HÀ TRIỀU | C10: DL031137762 | D10: 6 | E10: 29000000 | F10: Y | G10: A | I10: =CONVERT!B9 -> 26000 | J10: =CONVERT!AM9 -> 261000 | K10: =CONVERT!AL9 -> 0.9
A11: 45638 | B11: LÊ HÀ TRIỀU | C11: DL031137763 | D11: 6 | E11: 9000000 | F11: Y | G11: D | I11: =CONVERT!B10 -> 10000 | J11: =CONVERT!AM10 -> 0 | K11: =CONVERT!AL10 -> 0
A12: 45639 | B12: LÊ HÀ TRIỀU | C12: DL031137764 | D12: 5 | E12: 29000000 | F12: Y | G12: A | I12: =CONVERT!B11 -> 26000 | J12: =CONVERT!AM11 -> 261000 | K12: =CONVERT!AL11 -> 0.9
A13: 45640 | B13: LÊ HÀ TRIỀU | C13: DL031137765 | D13: 18 | E13: 9000000 | F13: Y | G13: A | I13: =CONVERT!B12 -> 20000 | J13: =CONVERT!AM12 -> 135000 | K13: =CONVERT!AL12 -> 1.5
A14: 45641 | B14: LÊ HÀ TRIỀU | C14: DL031137766 | D14: 18 | E14: 9000000 | F14: Y | G14: D | I14: =CONVERT!B13 -> 20000 | J14: =CONVERT!AM13 -> 0 | K14: =CONVERT!AL13 -> 0
... A21: 45648 | B21: LÊ HÀ TRIỀU | C21: DL031137773 | D21: 18 | E21: 29000000 | F21: Y | G21: B | I21: =CONVERT!B20 -> 36000 | J21: =CONVERT!AM20 -> 377000 | K21: =CONVERT!AL20 -> 1.3
I108: =CONVERT!B107 -> 0 | J108: =CONVERT!AM107 -> 0 | K108: =CONVERT!AL107 -> 0
I109: =CONVERT!B108 -> 0 | J109: =CONVERT!AM108 -> 0 | K109: =CONVERT!AL108 -> 0
I110: =CONVERT!B109 -> 0 | J110: =CONVERT!AM109 -> 0 | K110: =CONVERT!AL109 -> 0
I111: =CONVERT!B110 -> 0 | J111: =CONVERT!AM110 -> 0 | K111: =CONVERT!AL110 -> 0
I112: =CONVERT!B111 -> 0 | J112: =CONVERT!AM111 -> 0 | K112: =CONVERT!AL111 -> 0
I113: =CONVERT!B112 -> 0 | J113: =CONVERT!AM112 -> 0 | K113: =CONVERT!AL112 -> 0
I114: =CONVERT!B113 -> 0 | J114: =CONVERT!AM113 -> 0 | K114: =CONVERT!AL113 -> 0
I115: =CONVERT!B114 -> 0 | J115: =CONVERT!AM114 -> 0 | K115: =CONVERT!AL114 -> 0
I116: =CONVERT!B115 -> 0 | J116: =CONVERT!AM115 -> 0 | K116: =CONVERT!AL115 -> 0
I117: =CONVERT!B116 -> 0 | J117: =CONVERT!AM116 -> 0 | K117: =CONVERT!AL116 -> 0
I118: =CONVERT!B117 -> 0 | J118: =CONVERT!AM117 -> 0 | K118: =CONVERT!AL117 -> 0
I119: =CONVERT!B118 -> 0 | J119: =CONVERT!AM118 -> 0 | K119: =CONVERT!AL118 -> 0
... I169: =CONVERT!B168 -> 0 | J169: =CONVERT!AM168 -> 0 | K169: =CONVERT!AL168 -> 0
I170: =CONVERT!B169 -> 0 | K170: =CONVERT!AL169 -> 0
I171: =CONVERT!B170 -> 0 | K171: =CONVERT!AL170 -> 0
K172: =CONVERT!AL171 -> 0
K173: =CONVERT!AL172 -> 0
K174: =CONVERT!AL173 -> 0
K175: =CONVERT!AL174 -> 0
K176: =CONVERT!AL175 -> 0
K177: =CONVERT!AL176 -> 0
K178: =CONVERT!AL177 -> 0
K179: =CONVERT!AL178 -> 0
K180: =CONVERT!AL179 -> 0
K181: =CONVERT!AL180 -> 0
...

Sheet Sheet1
A1: 44959 | B1: NGUYỄN ĐẶNG HOÀNG GIA | C1: ED026292276 | D1: 6 | E1: 8000000 | F1: Y
A2: 44959 | B2: NGUYỄN ĐẶNG HOÀNG GIA | C2: ED026292276 | D2: 6 | E2: 8000000 | F2: Y
A3: 44959 | B3: NGUYỄN ĐẶNG HOÀNG GIA | C3: ED026292276 | D3: 6 | E3: 8000000 | F3: Y
A4: 44959 | B4: NGUYỄN ĐẶNG HOÀNG GIA | C4: ED026292276 | D4: 6 | E4: 8000000 | F4: Y
A5: 44959 | B5: NGUYỄN ĐẶNG HOÀNG GIA | C5: ED026292276 | D5: 6 | E5: 8000000 | F5: Y
A6: 44959 | B6: NGUYỄN ĐẶNG HOÀNG GIA | C6: ED026292276 | D6: 6 | E6: 8000000 | F6: Y
A7: 44959 | B7: NGUYỄN ĐẶNG HOÀNG GIA | C7: ED026292276 | D7: 6 | E7: 8000000 | F7: Y
A8: 44959 | B8: NGUYỄN ĐẶNG HOÀNG GIA | C8: ED026292276 | D8: 6 | E8: 8000000 | F8: Y
A9: 44959 | B9: NGUYỄN ĐẶNG HOÀNG GIA | C9: ED026292276 | D9: 6 | E9: 8000000 | F9: Y
A10: 44959 | B10: NGUYỄN ĐẶNG HOÀNG GIA | C10: ED026292276 | D10: 6 | E10: 8000000 | F10: Y
A11: 44959 | B11: NGUYỄN ĐẶNG HOÀNG GIA | C11: ED026292276 | D11: 6 | E11: 8000000 | F11: Y
A12: 44959 | B12: NGUYỄN ĐẶNG HOÀNG GIA | C12: ED026292276 | D12: 6 | E12: 8000000 | F12: Y
... A167: 44959 | B167: NGUYỄN ĐẶNG HOÀNG GIA | C167: ED026292276 | D167: 6 | E167: 8000000 | F167: Y

Sheet CONVERT
A1: Bao HiemED | B1: Bao HiemED | C1: BH DL | D1: BH ED | E1: Tinh KYHTB | F1: Scheme Group | G1: KV ED | H1: HS TT SCHEME | I1: HS BANG A | J1: DOANH SO TINH THUONG ED | K1: DOANH SO TINH THUONG DL | L1: CT4CL | M1: THƯỞNG LỄ | N1: KVDL | O1: DIEM SCHEME | P1: HE SO | Q1: BAO HIEM | R1: Kỳ hạn ASM | S1: Thời Hạn | T1: HS Tháng | V1: Hệ Số Kỳ Hạn | W1: %Tính Incneitve | X1: Khoan vay | Y1: schemes | AB1: Hệ Số % | AC1: 1 | AE1: BH DL | AF1: Thuong truc tiếp | AG1: BH DL | AI1: Số Lượng BH ED | AJ1: Số Lượng BH DL | AK1: HE SO BH | AL1: Hệ Số Kỳ Hạn Tháng | AM1: Thưởng Doanh Số | AN1: Bao Hiem
A2: =IF(D2="A",_xlfn.IFNA(INDEX(Data!$H$24:$J$28,MATCH('DL 1'!E3,Data!$G$24:$G$28,1),MATCH('DL 1'!D3,Data!$H$23:$J$23,1)),0),0) -> 0 | B2: =IF('DL 1'!F3="Y",Q2,0) -> 0 | C2: =_xlfn.IFNA(INDEX(Data!$H$24:$J$28,MATCH(#REF!,Data!$G$24:$G$28,1),MATCH(#REF!,Data!$H$23:$J$23,1)),0) -> #REF! | D2: =RIGHT(TRIM('DL 1'!G3),1) -> B | E2: ='DL 1'!E3*'DL 1'!D3 -> 261000000 | F2: =_xlfn.IFNA(VLOOKUP(TRIM('DL 1'!G3),Data!$A:$C,3,0),"") | G2: ='DL 1'!E3 -> 29000000 | H2: =_xlfn.IFNA(VLOOKUP(TRIM('DL 1'!G3),Data!$A:$D,4,0),0) -> 0 | I2: =_xlfn.IFNA(INDEX(Data!H70:K74,MATCH(Table7[[#This Row],[Column9]],Data!H69:K69,1),MATCH(CONVERT!#REF!,Data!G70:G74,1)),0) -> 0 | J2: =_xlfn.IFNA(IF(VLOOKUP(TRIM('DL 1'!G3),Data!$A:$C,3,0)="ST1",H2*I2*G2,IF(VLOOKUP(TRIM('DL 1'!G3),Data!$A:$C,3,0)="IR0",H2*G2,MIN(H2:I2)*G2)),0) -> 0 | K2: =_xlfn.IFNA(VLOOKUP(TRIM(#REF!),Data!$A:$D,4,0)*#REF!,0) -> #REF! | L2: =IF(TRIM('DL 1'!G3)="EDCLNHT0IRNLI",20000,0) -> 0 | M2: =IF(ISERROR(MATCH('DL 1'!A3,#REF!,0)),0,J2*2) -> 0 | N2: =#REF! -> #REF! | O2: =_xlfn.IFNA(VLOOKUP(RIGHT(VLOOKUP(TRIM('DL 1'!G3),Data!$A:$B,2,0),1),Data!$L$23:$M$30,2,0),0) -> 0 | P2: =IF(G2<1,0,IF(G2<12000000,1,IF(AND(G2>=12000000,G2<25000000),2,IF(AND(G2>=25000000,G2<50000000),3,IF(AND(G2>=50000000),4,))))) -> 3 | Q2: =IF(AND(P2=1,S2<15),10000,IF(AND(P2=1,S2>=15,S2<18),15000,IF(AND(P2=1,S2>=18),20000,(IF(AND(P2=2,S2<15),18000,IF(AND(P2=2,S2>=15,S2<18),23000,IF(AND(P2=2,S2>=18),28000,IF(AND(P2=3,S2<15),26000,IF(AND(P2=3,S2>=15,S2<18),31000,IF(AND(P2=3,S2>=18),36000,IF(AND(P2=4,S2<15),34000,IF(AND(P2=4,S2>=15,S2<18),39000,IF(AND(P2=4,S2>=18),44000))))))))))))) -> 26000 | R2: =INCENTIVE!$E$8 -> 130000000 | S2: ='DL 1'!D3 -> 9 | T2: =(IF(S2>=24,"5",IF(S2>=18,"4",IF(S2>=15,"3",IF(S2>=12,"2","1"))))) -> 1 | V2: =(IF(S2>=12,"6",IF(S2>=9,"5",IF(S2>=8,"4",IF(S2>=7,"3",IF(S2=6,"2","1")))))) -> 5 | W2: =IF(AND(V2="6",R2>=7.7),115%,IF(AND(V2="6",R2>=7.5),105%,IF(AND(V2="6",R2>=7.3),100%,IF(AND(V2="6",R2>=7),100%,IF(AND(V2="6",R2<7),100%,IF(AND(V2="5",R2>=7.7),110%,IF(AND(V2="5",R2>=7.5),100%,IF(AND(V2="5",R2>=7.3),100%,IF(AND(V2="5",R2>=7),100%,IF(AND(V2="5",R2<7),100%,IF(AND(V2="4",R2>=7.7),105%,IF(AND(V2="4",R2>=7.5),100%,IF(AND(V2="4",R2>=7.3),95%,IF(AND(V2="4",R2>=7),90%,IF(AND(V2="4",R2<7),80%,IF(AND(V2="3",R2>=7.7),100%,IF(AND(V2="3",R2>=7.5),90%,IF(AND(V2="3",R2>=7.3),80%,IF(AND(V2="3",R2>=7),70%,IF(AND(V2="3",R2<7),60%,IF(AND(V2="2",R2>=7.7),60%,IF(AND(V2="2",R2>=7.5),50%,IF(AND(V2="2",R2>=7.3),35%,IF(AND(V2="2",R2>=7),35%,IF(AND(V2="2",R2<7),25%,25%))))))))))))))))))))))))) -> 1.1 | X2: ='DL 1'!E3 -> 29000000 | Y2: ='DL 1'!G3 -> B | Z2: {=IF(AND(#REF!="1",Y2="A"),0.9,IF(AND(#REF!="1",Y2="B"),0.7,IF(AND(#REF!="1",Y2="C"),0,IF(AND(#REF!="1",Y2="D"),0,IF(AND(#REF!="2",Y2="A"),1.2,IF(AND(#REF!="2",Y2="B"),1,IF(AND(#REF!="2",Y2="C"),0.1,IF(AND(#REF!="2",Y2="D"),0,IF(AND(#REF!="3",Y2="A"),1.3,IF(AND(#REF!="3",Y2="B"),1.1,IF(AND(#REF!="3",Y2="C"),0.3,IF(AND(#REF!="3",Y2="D"),0,IF(AND(#REF!="4",Y2="A"),1.5,IF(AND(#REF!="4",Y2="B"),1.3,IF(AND(#REF!="4",Y2="C"),0.4,IF(AND(#REF!="4",Y2="D"),0,IF(AND(#REF!="5",Y2=”A”),1.6,IF(AND(#REF!="5",Y2="B"),1.4,IF(AND(#REF!="5",Y2="C"),0.5,IF(AND(#REF!="5",Y2="D"),0,))))))))))))))))))))} -> #REF! | AA2: =IF(AND(Y2="A",#REF!>1),1%,0) -> #REF! | AB2: =_xlfn.IFNA(INDEX(Data!$H$66:$L$69,MATCH('DL 1'!D3,Data!$G$66:$G$69,1),MATCH(CONVERT!#REF!,Data!$H$65:$L$65,1)),0) -> 0 | AC2: =IFERROR(VLOOKUP(Y2,Data!$G$65:$L$69,2,0) *X2,"") -> 20300000 | AD2: =SUM(AC2) -> 20300000 | AE2: ='DL 1'!F3 -> N | AF2: =IFERROR(VLOOKUP(Y2,Data!$G$65:$K$79,4,0),"") -> 1.1 | AG2: =#REF! -> #REF! | AI2: =COUNTIF(CONVERT!AE:AE,"Y") -> 17 | AJ2: =COUNTIF(CONVERT!AG:AG,"Y") -> 0 | AK2: =IF(G2<1,0,IF(G2<12000000,1,IF(AND(G2>=12000000,G2<25000000),2,IF(AND(G2>=25000000,G2<50000000),3,IF(AND(G2>=50000000),4,))))) -> 3 | AL2: =IF(AND(S2<12,Y2="A"),0.9,IF(AND(S2<12,Y2="B"),0.7,IF(AND(S2<12,Y2="C"),0,IF(AND(S2<12,Y2="D"),0,IF(AND(S2>=12,S2<15,Y2="A"),1.2,IF(AND(S2>=12,S2<15,Y2="B"),1,IF(AND(S2>=12,S2<15,Y2="C"),0.1,IF(AND(S2>=12,S2<15,Y2="D"),0,IF(AND(S2>=15,S2<18,Y2="A"),1.3,IF(AND(S2>=15,S2<18,Y2="B"),1.1,IF(AND(S2>=15,S2<18,Y2="C"),0.3,IF(AND(S2>=15,S2<18,Y2="D"),0,IF(AND(S2>=18,S2<24,Y2="A"),1.5,IF(AND(S2>=18,S2<24,Y2="B"),1.3,IF(AND(S2>=18,S2<24,Y2="C"),0.4,IF(AND(S2>=18,S2<24,Y2="D"),0,IF(AND(S2>=24,Y2="A"),1.6,IF(AND(S2>=24,Y2="B"),1.4,IF(AND(S2>=24,Y2="C"),0.5,IF(AND(S2>=24,Y2="D"),0,)))))))))))))))))))) -> 0.7 | AM2: =X2*(AL2/100) -> 203000 | AN2: =Q2 -> 26000
A3: =IF(D3="A",_xlfn.IFNA(INDEX(Data!$H$24:$J$28,MATCH('DL 1'!E4,Data!$G$24:$G$28,1),MATCH('DL 1'!D4,Data!$H$23:$J$23,1)),0),0) -> 25000 | B3: =IF('DL 1'!F4="Y",Q3,0) -> 10000 | C3: =_xlfn.IFNA(INDEX(Data!$H$24:$J$28,MATCH(#REF!,Data!$G$24:$G$28,1),MATCH(#REF!,Data!$H$23:$J$23,1)),0) -> #REF! | D3: =RIGHT(TRIM('DL 1'!G4),1) -> A | E3: ='DL 1'!E4*'DL 1'!D4 -> 120000000 | F3: =_xlfn.IFNA(VLOOKUP(TRIM('DL 1'!G4),Data!$A:$C,3,0),"") | G3: ='DL 1'!E4 -> 10000000 | H3: =_xlfn.IFNA(VLOOKUP(TRIM('DL 1'!G4),Data!$A:$D,4,0),0) -> 0 | I3: =_xlfn.IFNA(INDEX(Data!H71:K75,MATCH(Table7[[#This Row],[Column9]],Data!H70:K70,1),MATCH(CONVERT!#REF!,Data!G71:G75,1)),0) -> 0 | J3: =_xlfn.IFNA(IF(VLOOKUP(TRIM('DL 1'!G4),Data!$A:$C,3,0)="ST1",H3*I3*G3,IF(VLOOKUP(TRIM('DL 1'!G4),Data!$A:$C,3,0)="IR0",H3*G3,MIN(H3:I3)*G3)),0) -> 0 | K3: =_xlfn.IFNA(VLOOKUP(TRIM(#REF!),Data!$A:$D,4,0)*#REF!,0) -> #REF! | L3: =IF(TRIM('DL 1'!G4)="EDCLNHT0IRNLI",20000,0) -> 0 | M3: =IF(ISERROR(MATCH('DL 1'!A4,#REF!,0)),0,J3*2) -> 0 | N3: =#REF! -> #REF! | O3: =_xlfn.IFNA(VLOOKUP(RIGHT(VLOOKUP(TRIM('DL 1'!G4),Data!$A:$B,2,0),1),Data!$L$23:$M$30,2,0),0) -> 0 | P3: =IF(G3<1,0,IF(G3<12000000,1,IF(AND(G3>=12000000,G3<25000000),2,IF(AND(G3>=25000000,G3<50000000),3,IF(AND(G3>=50000000),4,))))) -> 1 | Q3: =IF(AND(P3=1,S3<15),10000,IF(AND(P3=1,S3>=15,S3<18),15000,IF(AND(P3=1,S3>=18),20000,(IF(AND(P3=2,S3<15),18000,IF(AND(P3=2,S3>=15,S3<18),23000,IF(AND(P3=2,S3>=18),28000,IF(AND(P3=3,S3<15),26000,IF(AND(P3=3,S3>=15,S3<18),31000,IF(AND(P3=3,S3>=18),36000,IF(AND(P3=4,S3<15),34000,IF(AND(P3=4,S3>=15,S3<18),39000,IF(AND(P3=4,S3>=18),44000))))))))))))) -> 10000 | R3: =INCENTIVE!$E$8 -> 130000000 | S3: ='DL 1'!D4 -> 12 | T3: =(IF(S3>=24,"5",IF(S3>=18,"4",IF(S3>=15,"3",IF(S3>=12,"2","1"))))) -> 2 | V3: =(IF(S3>=12,"6",IF(S3>=9,"5",IF(S3>=8,"4",IF(S3>=7,"3",IF(S3=6,"2","1")))))) -> 6 | W3: =IF(AND(V3="6",R3>=7.7),115%,IF(AND(V3="6",R3>=7.5),105%,IF(AND(V3="6",R3>=7.3),100%,IF(AND(V3="6",R3>=7),100%,IF(AND(V3="6",R3<7),100%,IF(AND(V3="5",R3>=7.7),110%,IF(AND(V3="5",R3>=7.5),100%,IF(AND(V3="5",R3>=7.3),100%,IF(AND(V3="5",R3>=7),100%,IF(AND(V3="5",R3<7),100%,IF(AND(V3="4",R3>=7.7),105%,IF(AND(V3="4",R3>=7.5),100%,IF(AND(V3="4",R3>=7.3),95%,IF(AND(V3="4",R3>=7),90%,IF(AND(V3="4",R3<7),80%,IF(AND(V3="3",R3>=7.7),100%,IF(AND(V3="3",R3>=7.5),90%,IF(AND(V3="3",R3>=7.3),80%,IF(AND(V3="3",R3>=7),70%,IF(AND(V3="3",R3<7),60%,IF(AND(V3="2",R3>=7.7),60%,IF(AND(V3="2",R3>=7.5),50%,IF(AND(V3="2",R3>=7.3),35%,IF(AND(V3="2",R3>=7),35%,IF(AND(V3="2",R3<7),25%,25%))))))))))))))))))))))))) -> 1.15 | X3: ='DL 1'!E4 -> 10000000 | Y3: ='DL 1'!G4 -> A | Z3: =IF(AND(#REF!="1",Y3="A"),0.9,IF(AND(#REF!="1",Y3="B"),0.7,IF(AND(#REF!="1",Y3="C"),0,IF(AND(#REF!="1",Y3="D"),0,IF(AND(#REF!="2",Y3="A"),1.2,IF(AND(#REF!="2",Y3="B"),1,IF(AND(#REF!="2",Y3="C"),0.1,IF(AND(#REF!="2",Y3="D"),0,IF(AND(#REF!="3",Y3="A"),1.3,IF(AND(#REF!="3",Y3="B"),1.1,IF(AND(#REF!="3",Y3="C"),0.3,IF(AND(#REF!="3",Y3="D"),0,IF(AND(#REF!="4",Y3="A"),1.5,IF(AND(#REF!="4",Y3="B"),1.3,IF(AND(#REF!="4",Y3="C"),0.4,IF(AND(#REF!="4",Y3="D"),0,IF(AND(#REF!="5",Y3="A"),1.6,IF(AND(#REF!="5",Y3="B"),1.4,IF(AND(#REF!="5",Y3="C"),0.5,IF(AND(#REF!="5",Y3="D"),0,)))))))))))))))))))) -> #REF! | AB3: =_xlfn.IFNA(INDEX(Data!$H$66:$L$69,MATCH('DL 1'!D4,Data!$G$66:$G$69,1),MATCH(CONVERT!#REF!,Data!$H$65:$L$65,1)),0) -> 0 | AC3: =IFERROR(VLOOKUP(Y3,Data!$G$65:$L$69,2,0) *X3,"") -> 9000000 | AD3: =SUM(AC3) -> 9000000 | AE3: ='DL 1'!F4 -> Y | AF3: =IFERROR(VLOOKUP(Y3,Data!$G$65:$K$79,4,0),"") -> 1.3 | AG3: =#REF! -> #REF! | AK3: =IF(G3<1,0,IF(G3<12000000,1,IF(AND(G3>=12000000,G3<25000000),2,IF(AND(G3>=25000000,G3<50000000),3,IF(AND(G3>=50000000),4,))))) -> 1 | AL3: =IF(AND(S3<12,Y3="A"),0.9,IF(AND(S3<12,Y3="B"),0.7,IF(AND(S3<12,Y3="C"),0,IF(AND(S3<12,Y3="D"),0,IF(AND(S3>=12,S3<15,Y3="A"),1.2,IF(AND(S3>=12,S3<15,Y3="B"),1,IF(AND(S3>=12,S3<15,Y3="C"),0.1,IF(AND(S3>=12,S3<15,Y3="D"),0,IF(AND(S3>=15,S3<18,Y3="A"),1.3,IF(AND(S3>=15,S3<18,Y3="B"),1.1,IF(AND(S3>=15,S3<18,Y3="C"),0.3,IF(AND(S3>=15,S3<18,Y3="D"),0,IF(AND(S3>=18,S3<24,Y3="A"),1.5,IF(AND(S3>=18,S3<24,Y3="B"),1.3,IF(AND(S3>=18,S3<24,Y3="C"),0.4,IF(AND(S3>=18,S3<24,Y3="D"),0,IF(AND(S3>=24,Y3="A"),1.6,IF(AND(S3>=24,Y3="B"),1.4,IF(AND(S3>=24,Y3="C"),0.5,IF(AND(S3>=24,Y3="D"),0,)))))))))))))))))))) -> 1.2 | AM3: =X3*(AL3/100) -> 120000 | AN3: =Q3 -> 10000
A4: =IF(D4="A",_xlfn.IFNA(INDEX(Data!$H$24:$J$28,MATCH('DL 1'!E5,Data!$G$24:$G$28,1),MATCH('DL 1'!D5,Data!$H$23:$J$23,1)),0),0) -> 0 | B4: =IF('DL 1'!F5="Y",Q4,0) -> 0 | C4: =_xlfn.IFNA(INDEX(Data!$H$24:$J$28,MATCH(#REF!,Data!$G$24:$G$28,1),MATCH(#REF!,Data!$H$23:$J$23,1)),0) -> #REF! | D4: =RIGHT(TRIM('DL 1'!G5),1) -> B | E4: ='DL 1'!E5*'DL 1'!D5 -> 324000000 | F4: =_xlfn.IFNA(VLOOKUP(TRIM('DL 1'!G5),Data!$A:$C,3,0),"") | G4: ='DL 1'!E5 -> 9000000 | H4: =_xlfn.IFNA(VLOOKUP(TRIM('DL 1'!G5),Data!$A:$D,4,0),0) -> 0 | I4: =_xlfn.IFNA(INDEX(Data!$G$5:$K$10,MATCH('DL 1'!D5,Data!$F$5:$F$10,1),MATCH(_xlfn.SINGLE(#REF!),Data!$G$4:$K$4,1)),0) -> #REF! | J4: =_xlfn.IFNA(IF(VLOOKUP(TRIM('DL 1'!G5),Data!$A:$C,3,0)="ST1",H4*I4*G4,IF(VLOOKUP(TRIM('DL 1'!G5),Data!$A:$C,3,0)="IR0",H4*G4,MIN(H4:I4)*G4)),0) -> 0 | K4: =_xlfn.IFNA(VLOOKUP(TRIM(#REF!),Data!$A:$D,4,0)*#REF!,0) -> #REF! | L4: =IF(TRIM('DL 1'!G5)="EDCLNHT0IRNLI",20000,0) -> 0 | M4: =IF(ISERROR(MATCH('DL 1'!A5,#REF!,0)),0,J4*2) -> 0 | N4: =#REF! -> #REF! | O4: =_xlfn.IFNA(VLOOKUP(RIGHT(VLOOKUP(TRIM('DL 1'!G5),Data!$A:$B,2,0),1),Data!$L$23:$M$30,2,0),0) -> 0 | P4: =IF(G4<1,0,IF(G4<12000000,1,IF(AND(G4>=12000000,G4<25000000),2,IF(AND(G4>=25000000,G4<50000000),3,IF(AND(G4>=50000000),4,))))) -> 1 | Q4: =IF(AND(P4=1,S4<15),10000,IF(AND(P4=1,S4>=15,S4<18),15000,IF(AND(P4=1,S4>=18),20000,(IF(AND(P4=2,S4<15),18000,IF(AND(P4=2,S4>=15,S4<18),23000,IF(AND(P4=2,S4>=18),28000,IF(AND(P4=3,S4<15),26000,IF(AND(P4=3,S4>=15,S4<18),31000,IF(AND(P4=3,S4>=18),36000,IF(AND(P4=4,S4<15),34000,IF(AND(P4=4,S4>=15,S4<18),39000,IF(AND(P4=4,S4>=18),44000))))))))))))) -> 20000 | R4: =INCENTIVE!$E$8 -> 130000000 | S4: ='DL 1'!D5 -> 36 | T4: =(IF(S4>=24,"5",IF(S4>=18,"4",IF(S4>=15,"3",IF(S4>=12,"2","1"))))) -> 5 | V4: =(IF(S4>=12,"6",IF(S4>=9,"5",IF(S4>=8,"4",IF(S4>=7,"3",IF(S4=6,"2","1")))))) -> 6 | W4: =IF(AND(V4="6",R4>=7.7),115%,IF(AND(V4="6",R4>=7.5),105%,IF(AND(V4="6",R4>=7.3),100%,IF(AND(V4="6",R4>=7),100%,IF(AND(V4="6",R4<7),100%,IF(AND(V4="5",R4>=7.7),110%,IF(AND(V4="5",R4>=7.5),100%,IF(AND(V4="5",R4>=7.3),100%,IF(AND(V4="5",R4>=7),100%,IF(AND(V4="5",R4<7),100%,IF(AND(V4="4",R4>=7.7),105%,IF(AND(V4="4",R4>=7.5),100%,IF(AND(V4="4",R4>=7.3),95%,IF(AND(V4="4",R4>=7),90%,IF(AND(V4="4",R4<7),80%,IF(AND(V4="3",R4>=7.7),100%,IF(AND(V4="3",R4>=7.5),90%,IF(AND(V4="3",R4>=7.3),80%,IF(AND(V4="3",R4>=7),70%,IF(AND(V4="3",R4<7),60%,IF(AND(V4="2",R4>=7.7),60%,IF(AND(V4="2",R4>=7.5),50%,IF(AND(V4="2",R4>=7.3),35%,IF(AND(V4="2",R4>=7),35%,IF(AND(V4="2",R4<7),25%,25%))))))))))))))))))))))))) -> 1.15 | X4: ='DL 1'!E5 -> 9000000 | Y4: ='DL 1'!G5 -> B | Z4: =IF(AND(#REF!="1",Y4="A"),0.9,IF(AND(#REF!="1",Y4="B"),0.7,IF(AND(#REF!="1",Y4="C"),0,IF(AND(#REF!="1",Y4="D"),0,IF(AND(#REF!="2",Y4="A"),1.2,IF(AND(#REF!="2",Y4="B"),1,IF(AND(#REF!="2",Y4="C"),0.1,IF(AND(#REF!="2",Y4="D"),0,IF(AND(#REF!="3",Y4="A"),1.3,IF(AND(#REF!="3",Y4="B"),1.1,IF(AND(#REF!="3",Y4="C"),0.3,IF(AND(#REF!="3",Y4="D"),0,IF(AND(#REF!="4",Y4="A"),1.5,IF(AND(#REF!="4",Y4="B"),1.3,IF(AND(#REF!="4",Y4="C"),0.4,IF(AND(#REF!="4",Y4="D"),0,IF(AND(#REF!="5",Y4="A"),1.6,IF(AND(#REF!="5",Y4="B"),1.4,IF(AND(#REF!="5",Y4="C"),0.5,IF(AND(#REF!="5",Y4="D"),0,)))))))))))))))))))) -> #REF! | AB4: =_xlfn.IFNA(INDEX(Data!$H$66:$L$69,MATCH('DL 1'!D5,Data!$G$66:$G$69,1),MATCH(CONVERT!#REF!,Data!$H$65:$L$65,1)),0) -> 0 | AC4: =IFERROR(VLOOKUP(Y4,Data!$G$65:$L$69,2,0) *X4,"") -> 6300000 | AD4: =SUM(AC4) -> 6300000 | AE4: ='DL 1'!F5 -> N | AF4: =IFERROR(VLOOKUP(Y4,Data!$G$65:$K$79,4,0),"") -> 1.1 | AG4: =#REF! -> #REF! | AK4: =IF(G4<1,0,IF(G4<12000000,1,IF(AND(G4>=12000000,G4<25000000),2,IF(AND(G4>=25000000,G4<50000000),3,IF(AND(G4>=50000000),4,))))) -> 1 | AL4: =IF(AND(S4<12,Y4="A"),0.9,IF(AND(S4<12,Y4="B"),0.7,IF(AND(S4<12,Y4="C"),0,IF(AND(S4<12,Y4="D"),0,IF(AND(S4>=12,S4<15,Y4="A"),1.2,IF(AND(S4>=12,S4<15,Y4="B"),1,IF(AND(S4>=12,S4<15,Y4="C"),0.1,IF(AND(S4>=12,S4<15,Y4="D"),0,IF(AND(S4>=15,S4<18,Y4="A"),1.3,IF(AND(S4>=15,S4<18,Y4="B"),1.1,IF(AND(S4>=15,S4<18,Y4="C"),0.3,IF(AND(S4>=15,S4<18,Y4="D"),0,IF(AND(S4>=18,S4<24,Y4="A"),1.5,IF(AND(S4>=18,S4<24,Y4="B"),1.3,IF(AND(S4>=18,S4<24,Y4="C"),0.4,IF(AND(S4>=18,S4<24,Y4="D"),0,IF(AND(S4>=24,Y4="A"),1.6,IF(AND(S4>=24,Y4="B"),1.4,IF(AND(S4>=24,Y4="C"),0.5,IF(AND(S4>=24,Y4="D"),0,)))))))))))))))))))) -> 1.4 | AM4: =X4*(AL4/100) -> 126000 | AN4: =Q4 -> 20000
A5: =IF(D5="A",_xlfn.IFNA(INDEX(Data!$H$24:$J$28,MATCH('DL 1'!E6,Data!$G$24:$G$28,1),MATCH('DL 1'!D6,Data!$H$23:$J$23,1)),0),0) -> 40000 | B5: =IF('DL 1'!F6="Y",Q5,0) -> 36000 | C5: =_xlfn.IFNA(INDEX(Data!$H$24:$J$28,MATCH(#REF!,Data!$G$24:$G$28,1),MATCH(#REF!,Data!$H$23:$J$23,1)),0) -> #REF! | D5: =RIGHT(TRIM('DL 1'!G6),1) -> A | E5: ='DL 1'!E6*'DL 1'!D6 -> 435000000 | F5: =_xlfn.IFNA(VLOOKUP(TRIM('DL 1'!G6),Data!$A:$C,3,0),"") | G5: ='DL 1'!E6 -> 29000000 | H5: =_xlfn.IFNA(VLOOKUP(TRIM('DL 1'!G6),Data!$A:$D,4,0),0) -> 0 | I5: =_xlfn.IFNA(INDEX(Data!$G$5:$K$10,MATCH('DL 1'!D6,Data!$F$5:$F$10,1),MATCH(_xlfn.SINGLE(#REF!),Data!$G$4:$K$4,1)),0) -> #REF! | J5: =_xlfn.IFNA(IF(VLOOKUP(TRIM('DL 1'!G6),Data!$A:$C,3,0)="ST1",H5*I5*G5,IF(VLOOKUP(TRIM('DL 1'!G6),Data!$A:$C,3,0)="IR0",H5*G5,MIN(H5:I5)*G5)),0) -> 0 | K5: =_xlfn.IFNA(VLOOKUP(TRIM(#REF!),Data!$A:$D,4,0)*#REF!,0) -> #REF! | L5: =IF(TRIM('DL 1'!G6)="EDCLNHT0IRNLI",20000,0) -> 0 | M5: =IF(ISERROR(MATCH('DL 1'!A6,#REF!,0)),0,J5*2) -> 0 | N5: =#REF! -> #REF! | O5: =_xlfn.IFNA(VLOOKUP(RIGHT(VLOOKUP(TRIM('DL 1'!G6),Data!$A:$B,2,0),1),Data!$L$23:$M$30,2,0),0) -> 0 | P5: =IF(G5<1,0,IF(G5<12000000,1,IF(AND(G5>=12000000,G5<25000000),2,IF(AND(G5>=25000000,G5<50000000),3,IF(AND(G5>=50000000),4,))))) -> 3 | Q5: =IF(AND(P5=1,S5<15),10000,IF(AND(P5=1,S5>=15,S5<18),15000,IF(AND(P5=1,S5>=18),20000,(IF(AND(P5=2,S5<15),18000,IF(AND(P5=2,S5>=15,S5<18),23000,IF(AND(P5=2,S5>=18),28000,IF(AND(P5=3,S5<15),26000,IF(AND(P5=3,S5>=15,S5<18),31000,IF(AND(P5=3,S5>=18),36000,IF(AND(P5=4,S5<15),34000,IF(AND(P5=4,S5>=15,S5<18),39000,IF(AND(P5=4,S5>=18),44000))))))))))))) -> 36000 | R5: =INCENTIVE!$E$8 -> 130000000 | S5: 18 | T5: =(IF(S5>=24,"5",IF(S5>=18,"4",IF(S5>=15,"3",IF(S5>=12,"2","1"))))) -> 4 | V5: =(IF(S5>=12,"6",IF(S5>=9,"5",IF(S5>=8,"4",IF(S5>=7,"3",IF(S5=6,"2","1")))))) -> 6 | W5: =IF(AND(V5="6",R5>=7.7),115%,IF(AND(V5="6",R5>=7.5),105%,IF(AND(V5="6",R5>=7.3),100%,IF(AND(V5="6",R5>=7),100%,IF(AND(V5="6",R5<7),100%,IF(AND(V5="5",R5>=7.7),110%,IF(AND(V5="5",R5>=7.5),100%,IF(AND(V5="5",R5>=7.3),100%,IF(AND(V5="5",R5>=7),100%,IF(AND(V5="5",R5<7),100%,IF(AND(V5="4",R5>=7.7),105%,IF(AND(V5="4",R5>=7.5),100%,IF(AND(V5="4",R5>=7.3),95%,IF(AND(V5="4",R5>=7),90%,IF(AND(V5="4",R5<7),80%,IF(AND(V5="3",R5>=7.7),100%,IF(AND(V5="3",R5>=7.5),90%,IF(AND(V5="3",R5>=7.3),80%,IF(AND(V5="3",R5>=7),70%,IF(AND(V5="3",R5<7),60%,IF(AND(V5="2",R5>=7.7),60%,IF(AND(V5="2",R5>=7.5),50%,IF(AND(V5="2",R5>=7.3),35%,IF(AND(V5="2",R5>=7),35%,IF(AND(V5="2",R5<7),25%,25%))))))))))))))))))))))))) -> 1.15 | X5: ='DL 1'!E6 -> 29000000 | Y5: ='DL 1'!G6 -> A | Z5: =IF(AND(#REF!="1",Y5="A"),0.9,IF(AND(#REF!="1",Y5="B"),0.7,IF(AND(#REF!="1",Y5="C"),0,IF(AND(#REF!="1",Y5="D"),0,IF(AND(#REF!="2",Y5="A"),1.2,IF(AND(#REF!="2",Y5="B"),1,IF(AND(#REF!="2",Y5="C"),0.1,IF(AND(#REF!="2",Y5="D"),0,IF(AND(#REF!="3",Y5="A"),1.3,IF(AND(#REF!="3",Y5="B"),1.1,IF(AND(#REF!="3",Y5="C"),0.3,IF(AND(#REF!="3",Y5="D"),0,IF(AND(#REF!="4",Y5="A"),1.5,IF(AND(#REF!="4",Y5="B"),1.3,IF(AND(#REF!="4",Y5="C"),0.4,IF(AND(#REF!="4",Y5="D"),0,IF(AND(#REF!="5",Y5="A"),1.6,IF(AND(#REF!="5",Y5="B"),1.4,IF(AND(#REF!="5",Y5="C"),0.5,IF(AND(#REF!="5",Y5="D"),0,)))))))))))))))))))) -> #REF! | AB5: =_xlfn.IFNA(INDEX(Data!$H$66:$L$69,MATCH('DL 1'!D6,Data!$G$66:$G$69,1),MATCH(CONVERT!#REF!,Data!$H$65:$L$65,1)),0) -> 0 | AC5: =IFERROR(VLOOKUP(Y5,Data!$G$65:$L$69,2,0) *X5,"") -> 26100000 | AD5: =SUM(AC5) -> 26100000 | AE5: ='DL 1'!F6 -> Y | AF5: =IFERROR(VLOOKUP(Y5,Data!$G$65:$K$79,4,0),"") -> 1.3 | AG5: =#REF! -> #REF! | AK5: =IF(G5<1,0,IF(G5<12000000,1,IF(AND(G5>=12000000,G5<25000000),2,IF(AND(G5>=25000000,G5<50000000),3,IF(AND(G5>=50000000),4,))))) -> 3 | AL5: =IF(AND(S5<12,Y5="A"),0.9,IF(AND(S5<12,Y5="B"),0.7,IF(AND(S5<12,Y5="C"),0,IF(AND(S5<12,Y5="D"),0,IF(AND(S5>=12,S5<15,Y5="A"),1.2,IF(AND(S5>=12,S5<15,Y5="B"),1,IF(AND(S5>=12,S5<15,Y5="C"),0.1,IF(AND(S5>=12,S5<15,Y5="D"),0,IF(AND(S5>=15,S5<18,Y5="A"),1.3,IF(AND(S5>=15,S5<18,Y5="B"),1.1,IF(AND(S5>=15,S5<18,Y5="C"),0.3,IF(AND(S5>=15,S5<18,Y5="D"),0,IF(AND(S5>=18,S5<24,Y5="A"),1.5,IF(AND(S5>=18,S5<24,Y5="B"),1.3,IF(AND(S5>=18,S5<24,Y5="C"),0.4,IF(AND(S5>=18,S5<24,Y5="D"),0,IF(AND(S5>=24,Y5="A"),1.6,IF(AND(S5>=24,Y5="B"),1.4,IF(AND(S5>=24,Y5="C"),0.5,IF(AND(S5>=24,Y5="D"),0,)))))))))))))))))))) -> 1.5 | AM5: =X5*(AL5/100) -> 435000 | AN5: =Q5 -> 36000
A6: =IF(D6="A",_xlfn.IFNA(INDEX(Data!$H$24:$J$28,MATCH('DL 1'!E7,Data!$G$24:$G$28,1),MATCH('DL 1'!D7,Data!$H$23:$J$23,1)),0),0) -> 0 | B6: =IF('DL 1'!F7="Y",Q6,0) -> 31000 | C6: =_xlfn.IFNA(INDEX(Data!$H$24:$J$28,MATCH(#REF!,Data!$G$24:$G$28,1),MATCH(#REF!,Data!$H$23:$J$23,1)),0) -> #REF! | D6: =RIGHT(TRIM('DL 1'!G7),1) -> C | E6: ='DL 1'!E7*'DL 1'!D7 -> 435000000 | F6: =_xlfn.IFNA(VLOOKUP(TRIM('DL 1'!G7),Data!$A:$C,3,0),"") | G6: ='DL 1'!E7 -> 29000000 | H6: =_xlfn.IFNA(VLOOKUP(TRIM('DL 1'!G7),Data!$A:$D,4,0),0) -> 0 | I6: =_xlfn.IFNA(INDEX(Data!$G$5:$K$10,MATCH('DL 1'!D7,Data!$F$5:$F$10,1),MATCH(_xlfn.SINGLE(#REF!),Data!$G$4:$K$4,1)),0) -> #REF! | J6: =_xlfn.IFNA(IF(VLOOKUP(TRIM('DL 1'!G7),Data!$A:$C,3,0)="ST1",H6*I6*G6,IF(VLOOKUP(TRIM('DL 1'!G7),Data!$A:$C,3,0)="IR0",H6*G6,MIN(H6:I6)*G6)),0) -> 0 | K6: =_xlfn.IFNA(VLOOKUP(TRIM(#REF!),Data!$A:$D,4,0)*#REF!,0) -> #REF! | L6: =IF(TRIM('DL 1'!G7)="EDCLNHT0IRNLI",20000,0) -> 0 | M6: =IF(ISERROR(MATCH('DL 1'!A7,#REF!,0)),0,J6*2) -> 0 | N6: =#REF! -> #REF! | O6: =_xlfn.IFNA(VLOOKUP(RIGHT(VLOOKUP(TRIM('DL 1'!G7),Data!$A:$B,2,0),1),Data!$L$23:$M$30,2,0),0) -> 0 | P6: =IF(G6<1,0,IF(G6<12000000,1,IF(AND(G6>=12000000,G6<25000000),2,IF(AND(G6>=25000000,G6<50000000),3,IF(AND(G6>=50000000),4,))))) -> 3 | Q6: =IF(AND(P6=1,S6<15),10000,IF(AND(P6=1,S6>=15,S6<18),15000,IF(AND(P6=1,S6>=18),20000,(IF(AND(P6=2,S6<15),18000,IF(AND(P6=2,S6>=15,S6<18),23000,IF(AND(P6=2,S6>=18),28000,IF(AND(P6=3,S6<15),26000,IF(AND(P6=3,S6>=15,S6<18),31000,IF(AND(P6=3,S6>=18),36000,IF(AND(P6=4,S6<15),34000,IF(AND(P6=4,S6>=15,S6<18),39000,IF(AND(P6=4,S6>=18),44000))))))))))))) -> 31000 | R6: =INCENTIVE!$E$8 -> 130000000 | S6: ='DL 1'!D7 -> 15 | T6: =(IF(S6>=24,"5",IF(S6>=18,"4",IF(S6>=15,"3",IF(S6>=12,"2","1"))))) -> 3 | V6: =(IF(S6>=12,"6",IF(S6>=9,"5",IF(S6>=8,"4",IF(S6>=7,"3",IF(S6=6,"2","1")))))) -> 6 | W6: =IF(AND(V6="6",R6>=7.7),115%,IF(AND(V6="6",R6>=7.5),105%,IF(AND(V6="6",R6>=7.3),100%,IF(AND(V6="6",R6>=7),100%,IF(AND(V6="6",R6<7),100%,IF(AND(V6="5",R6>=7.7),110%,IF(AND(V6="5",R6>=7.5),100%,IF(AND(V6="5",R6>=7.3),100%,IF(AND(V6="5",R6>=7),100%,IF(AND(V6="5",R6<7),100%,IF(AND(V6="4",R6>=7.7),105%,IF(AND(V6="4",R6>=7.5),100%,IF(AND(V6="4",R6>=7.3),95%,IF(AND(V6="4",R6>=7),90%,IF(AND(V6="4",R6<7),80%,IF(AND(V6="3",R6>=7.7),100%,IF(AND(V6="3",R6>=7.5),90%,IF(AND(V6="3",R6>=7.3),80%,IF(AND(V6="3",R6>=7),70%,IF(AND(V6="3",R6<7),60%,IF(AND(V6="2",R6>=7.7),60%,IF(AND(V6="2",R6>=7.5),50%,IF(AND(V6="2",R6>=7.3),35%,IF(AND(V6="2",R6>=7),35%,IF(AND(V6="2",R6<7),25%,25%))))))))))))))))))))))))) -> 1.15 | X6: ='DL 1'!E7 -> 29000000 | Y6: ='DL 1'!G7 -> C | Z6: =IF(AND(#REF!="1",Y6="A"),0.9,IF(AND(#REF!="1",Y6="B"),0.7,IF(AND(#REF!="1",Y6="C"),0,IF(AND(#REF!="1",Y6="D"),0,IF(AND(#REF!="2",Y6="A"),1.2,IF(AND(#REF!="2",Y6="B"),1,IF(AND(#REF!="2",Y6="C"),0.1,IF(AND(#REF!="2",Y6="D"),0,IF(AND(#REF!="3",Y6="A"),1.3,IF(AND(#REF!="3",Y6="B"),1.1,IF(AND(#REF!="3",Y6="C"),0.3,IF(AND(#REF!="3",Y6="D"),0,IF(AND(#REF!="4",Y6="A"),1.5,IF(AND(#REF!="4",Y6="B"),1.3,IF(AND(#REF!="4",Y6="C"),0.4,IF(AND(#REF!="4",Y6="D"),0,IF(AND(#REF!="5",Y6="A"),1.6,IF(AND(#REF!="5",Y6="B"),1.4,IF(AND(#REF!="5",Y6="C"),0.5,IF(AND(#REF!="5",Y6="D"),0,)))))))))))))))))))) -> #REF! | AB6: =_xlfn.IFNA(INDEX(Data!$H$66:$L$69,MATCH('DL 1'!D7,Data!$G$66:$G$69,1),MATCH(CONVERT!#REF!,Data!$H$65:$L$65,1)),0) -> 0 | AC6: =IFERROR(VLOOKUP(Y6,Data!$G$65:$L$69,2,0) *X6,"") -> 0 | AD6: =SUM(AC6) -> 0 | AE6: ='DL 1'!F7 -> Y | AF6: =IFERROR(VLOOKUP(Y6,Data!$G$65:$K$79,4,0),"") -> 0.3 | AG6: =#REF! -> #REF! | AK6: =IF(G6<1,0,IF(G6<12000000,1,IF(AND(G6>=12000000,G6<25000000),2,IF(AND(G6>=25000000,G6<50000000),3,IF(AND(G6>=50000000),4,))))) -> 3 | AL6: =IF(AND(S6<12,Y6="A"),0.9,IF(AND(S6<12,Y6="B"),0.7,IF(AND(S6<12,Y6="C"),0,IF(AND(S6<12,Y6="D"),0,IF(AND(S6>=12,S6<15,Y6="A"),1.2,IF(AND(S6>=12,S6<15,Y6="B"),1,IF(AND(S6>=12,S6<15,Y6="C"),0.1,IF(AND(S6>=12,S6<15,Y6="D"),0,IF(AND(S6>=15,S6<18,Y6="A"),1.3,IF(AND(S6>=15,S6<18,Y6="B"),1.1,IF(AND(S6>=15,S6<18,Y6="C"),0.3,IF(AND(S6>=15,S6<18,Y6="D"),0,IF(AND(S6>=18,S6<24,Y6="A"),1.5,IF(AND(S6>=18,S6<24,Y6="B"),1.3,IF(AND(S6>=18,S6<24,Y6="C"),0.4,IF(AND(S6>=18,S6<24,Y6="D"),0,IF(AND(S6>=24,Y6="A"),1.6,IF(AND(S6>=24,Y6="B"),1.4,IF(AND(S6>=24,Y6="C"),0.5,IF(AND(S6>=24,Y6="D"),0,)))))))))))))))))))) -> 0.3 | AM6: =X6*(AL6/100) -> 87000 | AN6: =Q6 -> 31000
A7: =IF(D7="A",_xlfn.IFNA(INDEX(Data!$H$24:$J$28,MATCH('DL 1'!E8,Data!$G$24:$G$28,1),MATCH('DL 1'!D8,Data!$H$23:$J$23,1)),0),0) -> 40000 | B7: =IF('DL 1'!F8="Y",Q7,0) -> 26000 | C7: =_xlfn.IFNA(INDEX(Data!$H$24:$J$28,MATCH(#REF!,Data!$G$24:$G$28,1),MATCH(#REF!,Data!$H$23:$J$23,1)),0) -> #REF! | D7: =RIGHT(TRIM('DL 1'!G8),1) -> A | E7: ='DL 1'!E8*'DL 1'!D8 -> 348000000 | F7: =_xlfn.IFNA(VLOOKUP(TRIM('DL 1'!G8),Data!$A:$C,3,0),"") | G7: ='DL 1'!E8 -> 29000000 | H7: =_xlfn.IFNA(VLOOKUP(TRIM('DL 1'!G8),Data!$A:$D,4,0),0) -> 0 | I7: =_xlfn.IFNA(INDEX(Data!$G$5:$K$10,MATCH('DL 1'!D8,Data!$F$5:$F$10,1),MATCH(_xlfn.SINGLE(#REF!),Data!$G$4:$K$4,1)),0) -> #REF! | J7: =_xlfn.IFNA(IF(VLOOKUP(TRIM('DL 1'!G8),Data!$A:$C,3,0)="ST1",H7*I7*G7,IF(VLOOKUP(TRIM('DL 1'!G8),Data!$A:$C,3,0)="IR0",H7*G7,MIN(H7:I7)*G7)),0) -> 0 | K7: =_xlfn.IFNA(VLOOKUP(TRIM(#REF!),Data!$A:$D,4,0)*#REF!,0) -> #REF! | L7: =IF(TRIM('DL 1'!G8)="EDCLNHT0IRNLI",20000,0) -> 0 | M7: =IF(ISERROR(MATCH('DL 1'!A8,#REF!,0)),0,J7*2) -> 0 | N7: =#REF! -> #REF! | O7: =_xlfn.IFNA(VLOOKUP(RIGHT(VLOOKUP(TRIM('DL 1'!G8),Data!$A:$B,2,0),1),Data!$L$23:$M$30,2,0),0) -> 0 | P7: =IF(G7<1,0,IF(G7<12000000,1,IF(AND(G7>=12000000,G7<25000000),2,IF(AND(G7>=25000000,G7<50000000),3,IF(AND(G7>=50000000),4,))))) -> 3 | Q7: =IF(AND(P7=1,S7<15),10000,IF(AND(P7=1,S7>=15,S7<18),15000,IF(AND(P7=1,S7>=18),20000,(IF(AND(P7=2,S7<15),18000,IF(AND(P7=2,S7>=15,S7<18),23000,IF(AND(P7=2,S7>=18),28000,IF(AND(P7=3,S7<15),26000,IF(AND(P7=3,S7>=15,S7<18),31000,IF(AND(P7=3,S7>=18),36000,IF(AND(P7=4,S7<15),34000,IF(AND(P7=4,S7>=15,S7<18),39000,IF(AND(P7=4,S7>=18),44000))))))))))))) -> 26000 | R7: =INCENTIVE!$E$8 -> 130000000 | S7: ='DL 1'!D8 -> 12 | T7: =(IF(S7>=24,"5",IF(S7>=18,"4",IF(S7>=15,"3",IF(S7>=12,"2","1"))))) -> 2 | V7: =(IF(S7>=12,"6",IF(S7>=9,"5",IF(S7>=8,"4",IF(S7>=7,"3",IF(S7=6,"2","1")))))) -> 6 | W7: =IF(AND(V7="6",R7>=7.7),115%,IF(AND(V7="6",R7>=7.5),105%,IF(AND(V7="6",R7>=7.3),100%,IF(AND(V7="6",R7>=7),100%,IF(AND(V7="6",R7<7),100%,IF(AND(V7="5",R7>=7.7),110%,IF(AND(V7="5",R7>=7.5),100%,IF(AND(V7="5",R7>=7.3),100%,IF(AND(V7="5",R7>=7),100%,IF(AND(V7="5",R7<7),100%,IF(AND(V7="4",R7>=7.7),105%,IF(AND(V7="4",R7>=7.5),100%,IF(AND(V7="4",R7>=7.3),95%,IF(AND(V7="4",R7>=7),90%,IF(AND(V7="4",R7<7),80%,IF(AND(V7="3",R7>=7.7),100%,IF(AND(V7="3",R7>=7.5),90%,IF(AND(V7="3",R7>=7.3),80%,IF(AND(V7="3",R7>=7),70%,IF(AND(V7="3",R7<7),60%,IF(AND(V7="2",R7>=7.7),60%,IF(AND(V7="2",R7>=7.5),50%,IF(AND(V7="2",R7>=7.3),35%,IF(AND(V7="2",R7>=7),35%,IF(AND(V7="2",R7<7),25%,25%))))))))))))))))))))))))) -> 1.15 | X7: ='DL 1'!E8 -> 29000000 | Y7: ='DL 1'!G8 -> A | Z7: =IF(AND(#REF!="1",Y7="A"),0.9,IF(AND(#REF!="1",Y7="B"),0.7,IF(AND(#REF!="1",Y7="C"),0,IF(AND(#REF!="1",Y7="D"),0,IF(AND(#REF!="2",Y7="A"),1.2,IF(AND(#REF!="2",Y7="B"),1,IF(AND(#REF!="2",Y7="C"),0.1,IF(AND(#REF!="2",Y7="D"),0,IF(AND(#REF!="3",Y7="A"),1.3,IF(AND(#REF!="3",Y7="B"),1.1,IF(AND(#REF!="3",Y7="C"),0.3,IF(AND(#REF!="3",Y7="D"),0,IF(AND(#REF!="4",Y7="A"),1.5,IF(AND(#REF!="4",Y7="B"),1.3,IF(AND(#REF!="4",Y7="C"),0.4,IF(AND(#REF!="4",Y7="D"),0,IF(AND(#REF!="5",Y7="A"),1.6,IF(AND(#REF!="5",Y7="B"),1.4,IF(AND(#REF!="5",Y7="C"),0.5,IF(AND(#REF!="5",Y7="D"),0,)))))))))))))))))))) -> #REF! | AB7: =_xlfn.IFNA(INDEX(Data!$H$66:$L$69,MATCH('DL 1'!D8,Data!$G$66:$G$69,1),MATCH(CONVERT!#REF!,Data!$H$65:$L$65,1)),0) -> 0 | AC7: =IFERROR(VLOOKUP(Y7,Data!$G$65:$L$69,2,0) *X7,"") -> 26100000 | AD7: =SUM(AC7) -> 26100000 | AE7: ='DL 1'!F8 -> Y | AF7: =IFERROR(VLOOKUP(Y7,Data!$G$65:$K$79,4,0),"") -> 1.3 | AG7: =#REF! -> #REF! | AK7: =IF(G7<1,0,IF(G7<12000000,1,IF(AND(G7>=12000000,G7<25000000),2,IF(AND(G7>=25000000,G7<50000000),3,IF(AND(G7>=50000000),4,))))) -> 3 | AL7: =IF(AND(S7<12,Y7="A"),0.9,IF(AND(S7<12,Y7="B"),0.7,IF(AND(S7<12,Y7="C"),0,IF(AND(S7<12,Y7="D"),0,IF(AND(S7>=12,S7<15,Y7="A"),1.2,IF(AND(S7>=12,S7<15,Y7="B"),1,IF(AND(S7>=12,S7<15,Y7="C"),0.1,IF(AND(S7>=12,S7<15,Y7="D"),0,IF(AND(S7>=15,S7<18,Y7="A"),1.3,IF(AND(S7>=15,S7<18,Y7="B"),1.1,IF(AND(S7>=15,S7<18,Y7="C"),0.3,IF(AND(S7>=15,S7<18,Y7="D"),0,IF(AND(S7>=18,S7<24,Y7="A"),1.5,IF(AND(S7>=18,S7<24,Y7="B"),1.3,IF(AND(S7>=18,S7<24,Y7="C"),0.4,IF(AND(S7>=18,S7<24,Y7="D"),0,IF(AND(S7>=24,Y7="A"),1.6,IF(AND(S7>=24,Y7="B"),1.4,IF(AND(S7>=24,Y7="C"),0.5,IF(AND(S7>=24,Y7="D"),0,)))))))))))))))))))) -> 1.2 | AM7: =X7*(AL7/100) -> 348000 | AN7: =Q7 -> 26000
A8: =IF(D8="A",_xlfn.IFNA(INDEX(Data!$H$24:$J$28,MATCH('DL 1'!E9,Data!$G$24:$G$28,1),MATCH('DL 1'!D9,Data!$H$23:$J$23,1)),0),0) -> 0 | B8: =IF('DL 1'!F9="Y",Q8,0) -> 10000 | C8: =_xlfn.IFNA(INDEX(Data!$H$24:$J$28,MATCH(#REF!,Data!$G$24:$G$28,1),MATCH(#REF!,Data!$H$23:$J$23,1)),0) -> #REF! | D8: =RIGHT(TRIM('DL 1'!G9),1) -> C | E8: ='DL 1'!E9*'DL 1'!D9 -> 81000000 | F8: =_xlfn.IFNA(VLOOKUP(TRIM('DL 1'!G9),Data!$A:$C,3,0),"") | G8: ='DL 1'!E9 -> 9000000 | H8: =_xlfn.IFNA(VLOOKUP(TRIM('DL 1'!G9),Data!$A:$D,4,0),0) -> 0 | I8: =_xlfn.IFNA(INDEX(Data!$G$5:$K$10,MATCH('DL 1'!D9,Data!$F$5:$F$10,1),MATCH(_xlfn.SINGLE(#REF!),Data!$G$4:$K$4,1)),0) -> #REF! | J8: =_xlfn.IFNA(IF(VLOOKUP(TRIM('DL 1'!G9),Data!$A:$C,3,0)="ST1",H8*I8*G8,IF(VLOOKUP(TRIM('DL 1'!G9),Data!$A:$C,3,0)="IR0",H8*G8,MIN(H8:I8)*G8)),0) -> 0 | K8: =_xlfn.IFNA(VLOOKUP(TRIM(#REF!),Data!$A:$D,4,0)*#REF!,0) -> #REF! | L8: =IF(TRIM('DL 1'!G9)="EDCLNHT0IRNLI",20000,0) -> 0 | M8: =IF(ISERROR(MATCH('DL 1'!A9,#REF!,0)),0,J8*2) -> 0 | N8: =#REF! -> #REF! | O8: =_xlfn.IFNA(VLOOKUP(RIGHT(VLOOKUP(TRIM('DL 1'!G9),Data!$A:$B,2,0),1),Data!$L$23:$M$30,2,0),0) -> 0 | P8: =IF(G8<1,0,IF(G8<12000000,1,IF(AND(G8>=12000000,G8<25000000),2,IF(AND(G8>=25000000,G8<50000000),3,IF(AND(G8>=50000000),4,))))) -> 1 | Q8: =IF(AND(P8=1,S8<15),10000,IF(AND(P8=1,S8>=15,S8<18),15000,IF(AND(P8=1,S8>=18),20000,(IF(AND(P8=2,S8<15),18000,IF(AND(P8=2,S8>=15,S8<18),23000,IF(AND(P8=2,S8>=18),28000,IF(AND(P8=3,S8<15),26000,IF(AND(P8=3,S8>=15,S8<18),31000,IF(AND(P8=3,S8>=18),36000,IF(AND(P8=4,S8<15),34000,IF(AND(P8=4,S8>=15,S8<18),39000,IF(AND(P8=4,S8>=18),44000))))))))))))) -> 10000 | R8: =INCENTIVE!$E$8 -> 130000000 | S8: ='DL 1'!D9 -> 9 | T8: =(IF(S8>=24,"5",IF(S8>=18,"4",IF(S8>=15,"3",IF(S8>=12,"2","1"))))) -> 1 | V8: =(IF(S8>=12,"6",IF(S8>=9,"5",IF(S8>=8,"4",IF(S8>=7,"3",IF(S8=6,"2","1")))))) -> 5 | W8: =IF(AND(V8="6",R8>=7.7),115%,IF(AND(V8="6",R8>=7.5),105%,IF(AND(V8="6",R8>=7.3),100%,IF(AND(V8="6",R8>=7),100%,IF(AND(V8="6",R8<7),100%,IF(AND(V8="5",R8>=7.7),110%,IF(AND(V8="5",R8>=7.5),100%,IF(AND(V8="5",R8>=7.3),100%,IF(AND(V8="5",R8>=7),100%,IF(AND(V8="5",R8<7),100%,IF(AND(V8="4",R8>=7.7),105%,IF(AND(V8="4",R8>=7.5),100%,IF(AND(V8="4",R8>=7.3),95%,IF(AND(V8="4",R8>=7),90%,IF(AND(V8="4",R8<7),80%,IF(AND(V8="3",R8>=7.7),100%,IF(AND(V8="3",R8>=7.5),90%,IF(AND(V8="3",R8>=7.3),80%,IF(AND(V8="3",R8>=7),70%,IF(AND(V8="3",R8<7),60%,IF(AND(V8="2",R8>=7.7),60%,IF(AND(V8="2",R8>=7.5),50%,IF(AND(V8="2",R8>=7.3),35%,IF(AND(V8="2",R8>=7),35%,IF(AND(V8="2",R8<7),25%,25%))))))))))))))))))))))))) -> 1.1 | X8: ='DL 1'!E9 -> 9000000 | Y8: ='DL 1'!G9 -> C | Z8: =IF(AND(#REF!="1",Y8="A"),0.9,IF(AND(#REF!="1",Y8="B"),0.7,IF(AND(#REF!="1",Y8="C"),0,IF(AND(#REF!="1",Y8="D"),0,IF(AND(#REF!="2",Y8="A"),1.2,IF(AND(#REF!="2",Y8="B"),1,IF(AND(#REF!="2",Y8="C"),0.1,IF(AND(#REF!="2",Y8="D"),0,IF(AND(#REF!="3",Y8="A"),1.3,IF(AND(#REF!="3",Y8="B"),1.1,IF(AND(#REF!="3",Y8="C"),0.3,IF(AND(#REF!="3",Y8="D"),0,IF(AND(#REF!="4",Y8="A"),1.5,IF(AND(#REF!="4",Y8="B"),1.3,IF(AND(#REF!="4",Y8="C"),0.4,IF(AND(#REF!="4",Y8="D"),0,IF(AND(#REF!="5",Y8="A"),1.6,IF(AND(#REF!="5",Y8="B"),1.4,IF(AND(#REF!="5",Y8="C"),0.5,IF(AND(#REF!="5",Y8="D"),0,)))))))))))))))))))) -> #REF! | AB8: =_xlfn.IFNA(INDEX(Data!$H$66:$L$69,MATCH('DL 1'!D9,Data!$G$66:$G$69,1),MATCH(CONVERT!#REF!,Data!$H$65:$L$65,1)),0) -> 0 | AC8: =IFERROR(VLOOKUP(Y8,Data!$G$65:$L$69,2,0) *X8,"") -> 0 | AD8: =SUM(AC8) -> 0 | AE8: ='DL 1'!F9 -> Y | AF8: =IFERROR(VLOOKUP(Y8,Data!$G$65:$K$79,4,0),"") -> 0.3 | AG8: =#REF! -> #REF! | AK8: =IF(G8<1,0,IF(G8<12000000,1,IF(AND(G8>=12000000,G8<25000000),2,IF(AND(G8>=25000000,G8<50000000),3,IF(AND(G8>=50000000),4,))))) -> 1 | AL8: =IF(AND(S8<12,Y8="A"),0.9,IF(AND(S8<12,Y8="B"),0.7,IF(AND(S8<12,Y8="C"),0,IF(AND(S8<12,Y8="D"),0,IF(AND(S8>=12,S8<15,Y8="A"),1.2,IF(AND(S8>=12,S8<15,Y8="B"),1,IF(AND(S8>=12,S8<15,Y8="C"),0.1,IF(AND(S8>=12,S8<15,Y8="D"),0,IF(AND(S8>=15,S8<18,Y8="A"),1.3,IF(AND(S8>=15,S8<18,Y8="B"),1.1,IF(AND(S8>=15,S8<18,Y8="C"),0.3,IF(AND(S8>=15,S8<18,Y8="D"),0,IF(AND(S8>=18,S8<24,Y8="A"),1.5,IF(AND(S8>=18,S8<24,Y8="B"),1.3,IF(AND(S8>=18,S8<24,Y8="C"),0.4,IF(AND(S8>=18,S8<24,Y8="D"),0,IF(AND(S8>=24,Y8="A"),1.6,IF(AND(S8>=24,Y8="B"),1.4,IF(AND(S8>=24,Y8="C"),0.5,IF(AND(S8>=24,Y8="D"),0,)))))))))))))))))))) -> 0 | AM8: =X8*(AL8/100) -> 0 | AN8: =Q8 -> 10000
A9: =IF(D9="A",_xlfn.IFNA(INDEX(Data!$H$24:$J$28,MATCH('DL 1'!E10,Data!$G$24:$G$28,1),MATCH('DL 1'!D10,Data!$H$23:$J$23,1)),0),0) -> 35000 | B9: =IF('DL 1'!F10="Y",Q9,0) -> 26000 | C9: =_xlfn.IFNA(INDEX(Data!$H$24:$J$28,MATCH(#REF!,Data!$G$24:$G$28,1),MATCH(#REF!,Data!$H$23:$J$23,1)),0) -> #REF! | D9: =RIGHT(TRIM('DL 1'!G10),1) -> A | E9: ='DL 1'!E10*'DL 1'!D10 -> 174000000 | F9: =_xlfn.IFNA(VLOOKUP(TRIM('DL 1'!G10),Data!$A:$C,3,0),"") | G9: ='DL 1'!E10 -> 29000000 | H9: =_xlfn.IFNA(VLOOKUP(TRIM('DL 1'!G10),Data!$A:$D,4,0),0) -> 0 | I9: =_xlfn.IFNA(INDEX(Data!$G$5:$K$10,MATCH('DL 1'!D10,Data!$F$5:$F$10,1),MATCH(_xlfn.SINGLE(#REF!),Data!$G$4:$K$4,1)),0) -> #REF! | J9: =_xlfn.IFNA(IF(VLOOKUP(TRIM('DL 1'!G10),Data!$A:$C,3,0)="ST1",H9*I9*G9,IF(VLOOKUP(TRIM('DL 1'!G10),Data!$A:$C,3,0)="IR0",H9*G9,MIN(H9:I9)*G9)),0) -> 0 | K9: =_xlfn.IFNA(VLOOKUP(TRIM(#REF!),Data!$A:$D,4,0)*#REF!,0) -> #REF! | L9: =IF(TRIM('DL 1'!G10)="EDCLNHT0IRNLI",20000,0) -> 0 | M9: =IF(ISERROR(MATCH('DL 1'!A10,#REF!,0)),0,J9*2) -> 0 | N9: =#REF! -> #REF! | O9: =_xlfn.IFNA(VLOOKUP(RIGHT(VLOOKUP(TRIM('DL 1'!G10),Data!$A:$B,2,0),1),Data!$L$23:$M$30,2,0),0) -> 0 | P9: =IF(G9<1,0,IF(G9<12000000,1,IF(AND(G9>=12000000,G9<25000000),2,IF(AND(G9>=25000000,G9<50000000),3,IF(AND(G9>=50000000),4,))))) -> 3 | Q9: =IF(AND(P9=1,S9<15),10000,IF(AND(P9=1,S9>=15,S9<18),15000,IF(AND(P9=1,S9>=18),20000,(IF(AND(P9=2,S9<15),18000,IF(AND(P9=2,S9>=15,S9<18),23000,IF(AND(P9=2,S9>=18),28000,IF(AND(P9=3,S9<15),26000,IF(AND(P9=3,S9>=15,S9<18),31000,IF(AND(P9=3,S9>=18),36000,IF(AND(P9=4,S9<15),34000,IF(AND(P9=4,S9>=15,S9<18),39000,IF(AND(P9=4,S9>=18),44000))))))))))))) -> 26000 | R9: =INCENTIVE!$E$8 -> 130000000 | S9: ='DL 1'!D10 -> 6 | T9: =(IF(S9>=24,"5",IF(S9>=18,"4",IF(S9>=15,"3",IF(S9>=12,"2","1"))))) -> 1 | V9: =(IF(S9>=12,"6",IF(S9>=9,"5",IF(S9>=8,"4",IF(S9>=7,"3",IF(S9=6,"2","1")))))) -> 2 | W9: =IF(AND(V9="6",R9>=7.7),115%,IF(AND(V9="6",R9>=7.5),105%,IF(AND(V9="6",R9>=7.3),100%,IF(AND(V9="6",R9>=7),100%,IF(AND(V9="6",R9<7),100%,IF(AND(V9="5",R9>=7.7),110%,IF(AND(V9="5",R9>=7.5),100%,IF(AND(V9="5",R9>=7.3),100%,IF(AND(V9="5",R9>=7),100%,IF(AND(V9="5",R9<7),100%,IF(AND(V9="4",R9>=7.7),105%,IF(AND(V9="4",R9>=7.5),100%,IF(AND(V9="4",R9>=7.3),95%,IF(AND(V9="4",R9>=7),90%,IF(AND(V9="4",R9<7),80%,IF(AND(V9="3",R9>=7.7),100%,IF(AND(V9="3",R9>=7.5),90%,IF(AND(V9="3",R9>=7.3),80%,IF(AND(V9="3",R9>=7),70%,IF(AND(V9="3",R9<7),60%,IF(AND(V9="2",R9>=7.7),60%,IF(AND(V9="2",R9>=7.5),50%,IF(AND(V9="2",R9>=7.3),35%,IF(AND(V9="2",R9>=7),35%,IF(AND(V9="2",R9<7),25%,25%))))))))))))))))))))))))) -> 0.6 | X9: ='DL 1'!E10 -> 29000000 | Y9: ='DL 1'!G10 -> A | Z9: =IF(AND(#REF!="1",Y9="A"),0.9,IF(AND(#REF!="1",Y9="B"),0.7,IF(AND(#REF!="1",Y9="C"),0,IF(AND(#REF!="1",Y9="D"),0,IF(AND(#REF!="2",Y9="A"),1.2,IF(AND(#REF!="2",Y9="B"),1,IF(AND(#REF!="2",Y9="C"),0.1,IF(AND(#REF!="2",Y9="D"),0,IF(AND(#REF!="3",Y9="A"),1.3,IF(AND(#REF!="3",Y9="B"),1.1,IF(AND(#REF!="3",Y9="C"),0.3,IF(AND(#REF!="3",Y9="D"),0,IF(AND(#REF!="4",Y9="A"),1.5,IF(AND(#REF!="4",Y9="B"),1.3,IF(AND(#REF!="4",Y9="C"),0.4,IF(AND(#REF!="4",Y9="D"),0,IF(AND(#REF!="5",Y9="A"),1.6,IF(AND(#REF!="5",Y9="B"),1.4,IF(AND(#REF!="5",Y9="C"),0.5,IF(AND(#REF!="5",Y9="D"),0,)))))))))))))))))))) -> #REF! | AB9: =_xlfn.IFNA(INDEX(Data!$H$66:$L$69,MATCH('DL 1'!D10,Data!$G$66:$G$69,1),MATCH(CONVERT!#REF!,Data!$H$65:$L$65,1)),0) -> 0 | AC9: =IFERROR(VLOOKUP(Y9,Data!$G$65:$L$69,2,0) *X9,"") -> 26100000 | AD9: =SUM(AC9) -> 26100000 | AE9: ='DL 1'!F10 -> Y | AF9: =IFERROR(VLOOKUP(Y9,Data!$G$65:$K$79,4,0),"") -> 1.3 | AG9: =#REF! -> #REF! | AK9: =IF(G9<1,0,IF(G9<12000000,1,IF(AND(G9>=12000000,G9<25000000),2,IF(AND(G9>=25000000,G9<50000000),3,IF(AND(G9>=50000000),4,))))) -> 3 | AL9: =IF(AND(S9<12,Y9="A"),0.9,IF(AND(S9<12,Y9="B"),0.7,IF(AND(S9<12,Y9="C"),0,IF(AND(S9<12,Y9="D"),0,IF(AND(S9>=12,S9<15,Y9="A"),1.2,IF(AND(S9>=12,S9<15,Y9="B"),1,IF(AND(S9>=12,S9<15,Y9="C"),0.1,IF(AND(S9>=12,S9<15,Y9="D"),0,IF(AND(S9>=15,S9<18,Y9="A"),1.3,IF(AND(S9>=15,S9<18,Y9="B"),1.1,IF(AND(S9>=15,S9<18,Y9="C"),0.3,IF(AND(S9>=15,S9<18,Y9="D"),0,IF(AND(S9>=18,S9<24,Y9="A"),1.5,IF(AND(S9>=18,S9<24,Y9="B"),1.3,IF(AND(S9>=18,S9<24,Y9="C"),0.4,IF(AND(S9>=18,S9<24,Y9="D"),0,IF(AND(S9>=24,Y9="A"),1.6,IF(AND(S9>=24,Y9="B"),1.4,IF(AND(S9>=24,Y9="C"),0.5,IF(AND(S9>=24,Y9="D"),0,)))))))))))))))))))) -> 0.9 | AM9: =X9*(AL9/100) -> 261000 | AN9: =Q9 -> 26000
A10: =IF(D10="A",_xlfn.IFNA(INDEX(Data!$H$24:$J$28,MATCH('DL 1'!E11,Data!$G$24:$G$28,1),MATCH('DL 1'!D11,Data!$H$23:$J$23,1)),0),0) -> 0 | B10: =IF('DL 1'!F11="Y",Q10,0) -> 10000 | C10: =_xlfn.IFNA(INDEX(Data!$H$24:$J$28,MATCH(#REF!,Data!$G$24:$G$28,1),MATCH(#REF!,Data!$H$23:$J$23,1)),0) -> #REF! | D10: =RIGHT(TRIM('DL 1'!G11),1) -> D | E10: ='DL 1'!E11*'DL 1'!D11 -> 54000000 | F10: =_xlfn.IFNA(VLOOKUP(TRIM('DL 1'!G11),Data!$A:$C,3,0),"") | G10: ='DL 1'!E11 -> 9000000 | H10: =_xlfn.IFNA(VLOOKUP(TRIM('DL 1'!G11),Data!$A:$D,4,0),0) -> 0 | I10: =_xlfn.IFNA(INDEX(Data!$G$5:$K$10,MATCH('DL 1'!D11,Data!$F$5:$F$10,1),MATCH(_xlfn.SINGLE(#REF!),Data!$G$4:$K$4,1)),0) -> #REF! | J10: =_xlfn.IFNA(IF(VLOOKUP(TRIM('DL 1'!G11),Data!$A:$C,3,0)="ST1",H10*I10*G10,IF(VLOOKUP(TRIM('DL 1'!G11),Data!$A:$C,3,0)="IR0",H10*G10,MIN(H10:I10)*G10)),0) -> 0 | K10: =_xlfn.IFNA(VLOOKUP(TRIM(#REF!),Data!$A:$D,4,0)*#REF!,0) -> #REF! | L10: =IF(TRIM('DL 1'!G11)="EDCLNHT0IRNLI",20000,0) -> 0 | M10: =IF(ISERROR(MATCH('DL 1'!A11,#REF!,0)),0,J10*2) -> 0 | N10: =#REF! -> #REF! | O10: =_xlfn.IFNA(VLOOKUP(RIGHT(VLOOKUP(TRIM('DL 1'!G11),Data!$A:$B,2,0),1),Data!$L$23:$M$30,2,0),0) -> 0 | P10: =IF(G10<1,0,IF(G10<12000000,1,IF(AND(G10>=12000000,G10<25000000),2,IF(AND(G10>=25000000,G10<50000000),3,IF(AND(G10>=50000000),4,))))) -> 1 | Q10: =IF(AND(P10=1,S10<15),10000,IF(AND(P10=1,S10>=15,S10<18),15000,IF(AND(P10=1,S10>=18),20000,(IF(AND(P10=2,S10<15),18000,IF(AND(P10=2,S10>=15,S10<18),23000,IF(AND(P10=2,S10>=18),28000,IF(AND(P10=3,S10<15),26000,IF(AND(P10=3,S10>=15,S10<18),31000,IF(AND(P10=3,S10>=18),36000,IF(AND(P10=4,S10<15),34000,IF(AND(P10=4,S10>=15,S10<18),39000,IF(AND(P10=4,S10>=18),44000))))))))))))) -> 10000 | R10: =INCENTIVE!$E$8 -> 130000000 | S10: ='DL 1'!D11 -> 6 | T10: =(IF(S10>=24,"5",IF(S10>=18,"4",IF(S10>=15,"3",IF(S10>=12,"2","1"))))) -> 1 | V10: =(IF(S10>=12,"6",IF(S10>=9,"5",IF(S10>=8,"4",IF(S10>=7,"3",IF(S10=6,"2","1")))))) -> 2 | W10: =IF(AND(V10="6",R10>=7.7),115%,IF(AND(V10="6",R10>=7.5),105%,IF(AND(V10="6",R10>=7.3),100%,IF(AND(V10="6",R10>=7),100%,IF(AND(V10="6",R10<7),100%,IF(AND(V10="5",R10>=7.7),110%,IF(AND(V10="5",R10>=7.5),100%,IF(AND(V10="5",R10>=7.3),100%,IF(AND(V10="5",R10>=7),100%,IF(AND(V10="5",R10<7),100%,IF(AND(V10="4",R10>=7.7),105%,IF(AND(V10="4",R10>=7.5),100%,IF(AND(V10="4",R10>=7.3),95%,IF(AND(V10="4",R10>=7),90%,IF(AND(V10="4",R10<7),80%,IF(AND(V10="3",R10>=7.7),100%,IF(AND(V10="3",R10>=7.5),90%,IF(AND(V10="3",R10>=7.3),80%,IF(AND(V10="3",R10>=7),70%,IF(AND(V10="3",R10<7),60%,IF(AND(V10="2",R10>=7.7),60%,IF(AND(V10="2",R10>=7.5),50%,IF(AND(V10="2",R10>=7.3),35%,IF(AND(V10="2",R10>=7),35%,IF(AND(V10="2",R10<7),25%,25%))))))))))))))))))))))))) -> 0.6 | X10: ='DL 1'!E11 -> 9000000 | Y10: ='DL 1'!G11 -> D | Z10: =IF(AND(#REF!="1",Y10="A"),0.9,IF(AND(#REF!="1",Y10="B"),0.7,IF(AND(#REF!="1",Y10="C"),0,IF(AND(#REF!="1",Y10="D"),0,IF(AND(#REF!="2",Y10="A"),1.2,IF(AND(#REF!="2",Y10="B"),1,IF(AND(#REF!="2",Y10="C"),0.1,IF(AND(#REF!="2",Y10="D"),0,IF(AND(#REF!="3",Y10="A"),1.3,IF(AND(#REF!="3",Y10="B"),1.1,IF(AND(#REF!="3",Y10="C"),0.3,IF(AND(#REF!="3",Y10="D"),0,IF(AND(#REF!="4",Y10="A"),1.5,IF(AND(#REF!="4",Y10="B"),1.3,IF(AND(#REF!="4",Y10="C"),0.4,IF(AND(#REF!="4",Y10="D"),0,IF(AND(#REF!="5",Y10="A"),1.6,IF(AND(#REF!="5",Y10="B"),1.4,IF(AND(#REF!="5",Y10="C"),0.5,IF(AND(#REF!="5",Y10="D"),0,)))))))))))))))))))) -> #REF! | AB10: =_xlfn.IFNA(INDEX(Data!$H$66:$L$69,MATCH('DL 1'!D11,Data!$G$66:$G$69,1),MATCH(CONVERT!#REF!,Data!$H$65:$L$65,1)),0) -> 0 | AC10: =IFERROR(VLOOKUP(Y10,Data!$G$65:$L$69,2,0) *X10,"") -> 0 | AD10: =SUM(AC10) -> 0 | AE10: ='DL 1'!F11 -> Y | AF10: =IFERROR(VLOOKUP(Y10,Data!$G$65:$K$79,4,0),"") -> 0 | AG10: =#REF! -> #REF! | AK10: =IF(G10<1,0,IF(G10<12000000,1,IF(AND(G10>=12000000,G10<25000000),2,IF(AND(G10>=25000000,G10<50000000),3,IF(AND(G10>=50000000),4,))))) -> 1 | AL10: =IF(AND(S10<12,Y10="A"),0.9,IF(AND(S10<12,Y10="B"),0.7,IF(AND(S10<12,Y10="C"),0,IF(AND(S10<12,Y10="D"),0,IF(AND(S10>=12,S10<15,Y10="A"),1.2,IF(AND(S10>=12,S10<15,Y10="B"),1,IF(AND(S10>=12,S10<15,Y10="C"),0.1,IF(AND(S10>=12,S10<15,Y10="D"),0,IF(AND(S10>=15,S10<18,Y10="A"),1.3,IF(AND(S10>=15,S10<18,Y10="B"),1.1,IF(AND(S10>=15,S10<18,Y10="C"),0.3,IF(AND(S10>=15,S10<18,Y10="D"),0,IF(AND(S10>=18,S10<24,Y10="A"),1.5,IF(AND(S10>=18,S10<24,Y10="B"),1.3,IF(AND(S10>=18,S10<24,Y10="C"),0.4,IF(AND(S10>=18,S10<24,Y10="D"),0,IF(AND(S10>=24,Y10="A"),1.6,IF(AND(S10>=24,Y10="B"),1.4,IF(AND(S10>=24,Y10="C"),0.5,IF(AND(S10>=24,Y10="D"),0,)))))))))))))))))))) -> 0 | AM10: =X10*(AL10/100) -> 0 | AN10: =Q10 -> 10000
A11: =IF(D11="A",_xlfn.IFNA(INDEX(Data!$H$24:$J$28,MATCH('DL 1'!E12,Data!$G$24:$G$28,1),MATCH('DL 1'!D12,Data!$H$23:$J$23,1)),0),0) -> 25000 | B11: =IF('DL 1'!F12="Y",Q11,0) -> 26000 | C11: =_xlfn.IFNA(INDEX(Data!$H$24:$J$28,MATCH(#REF!,Data!$G$24:$G$28,1),MATCH(#REF!,Data!$H$23:$J$23,1)),0) -> #REF! | D11: =RIGHT(TRIM('DL 1'!G12),1) -> A | E11: ='DL 1'!E12*'DL 1'!D12 -> 145000000 | F11: =_xlfn.IFNA(VLOOKUP(TRIM('DL 1'!G12),Data!$A:$C,3,0),"") | G11: ='DL 1'!E12 -> 29000000 | H11: =_xlfn.IFNA(VLOOKUP(TRIM('DL 1'!G12),Data!$A:$D,4,0),0) -> 0 | I11: =_xlfn.IFNA(INDEX(Data!$G$5:$K$10,MATCH('DL 1'!D12,Data!$F$5:$F$10,1),MATCH(_xlfn.SINGLE(#REF!),Data!$G$4:$K$4,1)),0) -> #REF! | J11: =_xlfn.IFNA(IF(VLOOKUP(TRIM('DL 1'!G12),Data!$A:$C,3,0)="ST1",H11*I11*G11,IF(VLOOKUP(TRIM('DL 1'!G12),Data!$A:$C,3,0)="IR0",H11*G11,MIN(H11:I11)*G11)),0) -> 0 | K11: =_xlfn.IFNA(VLOOKUP(TRIM(#REF!),Data!$A:$D,4,0)*#REF!,0) -> #REF! | L11: =IF(TRIM('DL 1'!G12)="EDCLNHT0IRNLI",20000,0) -> 0 | M11: =IF(ISERROR(MATCH('DL 1'!A12,#REF!,0)),0,J11*2) -> 0 | N11: =#REF! -> #REF! | O11: =_xlfn.IFNA(VLOOKUP(RIGHT(VLOOKUP(TRIM('DL 1'!G12),Data!$A:$B,2,0),1),Data!$L$23:$M$30,2,0),0) -> 0 | P11: =IF(G11<1,0,IF(G11<12000000,1,IF(AND(G11>=12000000,G11<25000000),2,IF(AND(G11>=25000000,G11<50000000),3,IF(AND(G11>=50000000),4,))))) -> 3 | Q11: =IF(AND(P11=1,S11<15),10000,IF(AND(P11=1,S11>=15,S11<18),15000,IF(AND(P11=1,S11>=18),20000,(IF(AND(P11=2,S11<15),18000,IF(AND(P11=2,S11>=15,S11<18),23000,IF(AND(P11=2,S11>=18),28000,IF(AND(P11=3,S11<15),26000,IF(AND(P11=3,S11>=15,S11<18),31000,IF(AND(P11=3,S11>=18),36000,IF(AND(P11=4,S11<15),34000,IF(AND(P11=4,S11>=15,S11<18),39000,IF(AND(P11=4,S11>=18),44000))))))))))))) -> 26000 | R11: =INCENTIVE!$E$8 -> 130000000 | S11: ='DL 1'!D12 -> 5 | T11: =(IF(S11>=24,"5",IF(S11>=18,"4",IF(S11>=15,"3",IF(S11>=12,"2","1"))))) -> 1 | V11: =(IF(S11>=12,"6",IF(S11>=9,"5",IF(S11>=8,"4",IF(S11>=7,"3",IF(S11=6,"2","1")))))) -> 1 | W11: =IF(AND(V11="6",R11>=7.7),115%,IF(AND(V11="6",R11>=7.5),105%,IF(AND(V11="6",R11>=7.3),100%,IF(AND(V11="6",R11>=7),100%,IF(AND(V11="6",R11<7),100%,IF(AND(V11="5",R11>=7.7),110%,IF(AND(V11="5",R11>=7.5),100%,IF(AND(V11="5",R11>=7.3),100%,IF(AND(V11="5",R11>=7),100%,IF(AND(V11="5",R11<7),100%,IF(AND(V11="4",R11>=7.7),105%,IF(AND(V11="4",R11>=7.5),100%,IF(AND(V11="4",R11>=7.3),95%,IF(AND(V11="4",R11>=7),90%,IF(AND(V11="4",R11<7),80%,IF(AND(V11="3",R11>=7.7),100%,IF(AND(V11="3",R11>=7.5),90%,IF(AND(V11="3",R11>=7.3),80%,IF(AND(V11="3",R11>=7),70%,IF(AND(V11="3",R11<7),60%,IF(AND(V11="2",R11>=7.7),60%,IF(AND(V11="2",R11>=7.5),50%,IF(AND(V11="2",R11>=7.3),35%,IF(AND(V11="2",R11>=7),35%,IF(AND(V11="2",R11<7),25%,25%))))))))))))))))))))))))) -> 0.25 | X11: ='DL 1'!E12 -> 29000000 | Y11: ='DL 1'!G12 -> A | Z11: =IF(AND(#REF!="1",Y11="A"),0.9,IF(AND(#REF!="1",Y11="B"),0.7,IF(AND(#REF!="1",Y11="C"),0,IF(AND(#REF!="1",Y11="D"),0,IF(AND(#REF!="2",Y11="A"),1.2,IF(AND(#REF!="2",Y11="B"),1,IF(AND(#REF!="2",Y11="C"),0.1,IF(AND(#REF!="2",Y11="D"),0,IF(AND(#REF!="3",Y11="A"),1.3,IF(AND(#REF!="3",Y11="B"),1.1,IF(AND(#REF!="3",Y11="C"),0.3,IF(AND(#REF!="3",Y11="D"),0,IF(AND(#REF!="4",Y11="A"),1.5,IF(AND(#REF!="4",Y11="B"),1.3,IF(AND(#REF!="4",Y11="C"),0.4,IF(AND(#REF!="4",Y11="D"),0,IF(AND(#REF!="5",Y11="A"),1.6,IF(AND(#REF!="5",Y11="B"),1.4,IF(AND(#REF!="5",Y11="C"),0.5,IF(AND(#REF!="5",Y11="D"),0,)))))))))))))))))))) -> #REF! | AB11: =_xlfn.IFNA(INDEX(Data!$H$66:$L$69,MATCH('DL 1'!D12,Data!$G$66:$G$69,1),MATCH(CONVERT!#REF!,Data!$H$65:$L$65,1)),0) -> 0 | AC11: =_xlfn.IFNA(INDEX(Data!$H$66:$L$69,MATCH('DL 1'!D3,Data!$G$66:$G$69,1),MATCH(CONVERT!#REF!,Data!$H$65:$L$65,1)),0) -> 0 | AD11: =SUM(AC11) -> 0 | AE11: ='DL 1'!F12 -> Y | AF11: =IFERROR(VLOOKUP(Y11,Data!$G$65:$K$79,4,0),"") -> 1.3 | AG11: =#REF! -> #REF! | AK11: =IF(G11<1,0,IF(G11<12000000,1,IF(AND(G11>=12000000,G11<25000000),2,IF(AND(G11>=25000000,G11<50000000),3,IF(AND(G11>=50000000),4,))))) -> 3 | AL11: =IF(AND(S11<12,Y11="A"),0.9,IF(AND(S11<12,Y11="B"),0.7,IF(AND(S11<12,Y11="C"),0,IF(AND(S11<12,Y11="D"),0,IF(AND(S11>=12,S11<15,Y11="A"),1.2,IF(AND(S11>=12,S11<15,Y11="B"),1,IF(AND(S11>=12,S11<15,Y11="C"),0.1,IF(AND(S11>=12,S11<15,Y11="D"),0,IF(AND(S11>=15,S11<18,Y11="A"),1.3,IF(AND(S11>=15,S11<18,Y11="B"),1.1,IF(AND(S11>=15,S11<18,Y11="C"),0.3,IF(AND(S11>=15,S11<18,Y11="D"),0,IF(AND(S11>=18,S11<24,Y11="A"),1.5,IF(AND(S11>=18,S11<24,Y11="B"),1.3,IF(AND(S11>=18,S11<24,Y11="C"),0.4,IF(AND(S11>=18,S11<24,Y11="D"),0,IF(AND(S11>=24,Y11="A"),1.6,IF(AND(S11>=24,Y11="B"),1.4,IF(AND(S11>=24,Y11="C"),0.5,IF(AND(S11>=24,Y11="D"),0,)))))))))))))))))))) -> 0.9 | AM11: =X11*(AL11/100) -> 261000 | AN11: =Q11 -> 26000
A12: =IF(D12="A",_xlfn.IFNA(INDEX(Data!$H$24:$J$28,MATCH('DL 1'!E13,Data!$G$24:$G$28,1),MATCH('DL 1'!D13,Data!$H$23:$J$23,1)),0),0) -> 25000 | B12: =IF('DL 1'!F13="Y",Q12,0) -> 20000 | C12: =_xlfn.IFNA(INDEX(Data!$H$24:$J$28,MATCH(#REF!,Data!$G$24:$G$28,1),MATCH(#REF!,Data!$H$23:$J$23,1)),0) -> #REF! | D12: =RIGHT(TRIM('DL 1'!G13),1) -> A | E12: ='DL 1'!E13*'DL 1'!D13 -> 162000000 | F12: =_xlfn.IFNA(VLOOKUP(TRIM('DL 1'!G13),Data!$A:$C,3,0),"") | G12: ='DL 1'!E13 -> 9000000 | H12: =_xlfn.IFNA(VLOOKUP(TRIM('DL 1'!G13),Data!$A:$D,4,0),0) -> 0 | I12: =_xlfn.IFNA(INDEX(Data!$G$5:$K$10,MATCH('DL 1'!D13,Data!$F$5:$F$10,1),MATCH(_xlfn.SINGLE(#REF!),Data!$G$4:$K$4,1)),0) -> #REF! | J12: =_xlfn.IFNA(IF(VLOOKUP(TRIM('DL 1'!G13),Data!$A:$C,3,0)="ST1",H12*I12*G12,IF(VLOOKUP(TRIM('DL 1'!G13),Data!$A:$C,3,0)="IR0",H12*G12,MIN(H12:I12)*G12)),0) -> 0 | K12: =_xlfn.IFNA(VLOOKUP(TRIM(#REF!),Data!$A:$D,4,0)*#REF!,0) -> #REF! | L12: =IF(TRIM('DL 1'!G13)="EDCLNHT0IRNLI",20000,0) -> 0 | M12: =IF(ISERROR(MATCH('DL 1'!A13,#REF!,0)),0,J12*2) -> 0 | N12: =#REF! -> #REF! | O12: =_xlfn.IFNA(VLOOKUP(RIGHT(VLOOKUP(TRIM('DL 1'!G13),Data!$A:$B,2,0),1),Data!$L$23:$M$30,2,0),0) -> 0 | P12: =IF(G12<1,0,IF(G12<12000000,1,IF(AND(G12>=12000000,G12<25000000),2,IF(AND(G12>=25000000,G12<50000000),3,IF(AND(G12>=50000000),4,))))) -> 1 | Q12: =IF(AND(P12=1,S12<15),10000,IF(AND(P12=1,S12>=15,S12<18),15000,IF(AND(P12=1,S12>=18),20000,(IF(AND(P12=2,S12<15),18000,IF(AND(P12=2,S12>=15,S12<18),23000,IF(AND(P12=2,S12>=18),28000,IF(AND(P12=3,S12<15),26000,IF(AND(P12=3,S12>=15,S12<18),31000,IF(AND(P12=3,S12>=18),36000,IF(AND(P12=4,S12<15),34000,IF(AND(P12=4,S12>=15,S12<18),39000,IF(AND(P12=4,S12>=18),44000))))))))))))) -> 20000 | R12: =INCENTIVE!$E$8 -> 130000000 | S12: ='DL 1'!D13 -> 18 | T12: =(IF(S12>=24,"5",IF(S12>=18,"4",IF(S12>=15,"3",IF(S12>=12,"2","1"))))) -> 4 | V12: =(IF(S12>=12,"6",IF(S12>=9,"5",IF(S12>=8,"4",IF(S12>=7,"3",IF(S12=6,"2","1")))))) -> 6 | W12: =IF(AND(V12="6",R12>=7.7),115%,IF(AND(V12="6",R12>=7.5),105%,IF(AND(V12="6",R12>=7.3),100%,IF(AND(V12="6",R12>=7),100%,IF(AND(V12="6",R12<7),100%,IF(AND(V12="5",R12>=7.7),110%,IF(AND(V12="5",R12>=7.5),100%,IF(AND(V12="5",R12>=7.3),100%,IF(AND(V12="5",R12>=7),100%,IF(AND(V12="5",R12<7),100%,IF(AND(V12="4",R12>=7.7),105%,IF(AND(V12="4",R12>=7.5),100%,IF(AND(V12="4",R12>=7.3),95%,IF(AND(V12="4",R12>=7),90%,IF(AND(V12="4",R12<7),80%,IF(AND(V12="3",R12>=7.7),100%,IF(AND(V12="3",R12>=7.5),90%,IF(AND(V12="3",R12>=7.3),80%,IF(AND(V12="3",R12>=7),70%,IF(AND(V12="3",R12<7),60%,IF(AND(V12="2",R12>=7.7),60%,IF(AND(V12="2",R12>=7.5),50%,IF(AND(V12="2",R12>=7.3),35%,IF(AND(V12="2",R12>=7),35%,IF(AND(V12="2",R12<7),25%,25%))))))))))))))))))))))))) -> 1.15 | X12: ='DL 1'!E13 -> 9000000 | Y12: ='DL 1'!G13 -> A | Z12: =IF(AND(#REF!="1",Y12="A"),0.9,IF(AND(#REF!="1",Y12="B"),0.7,IF(AND(#REF!="1",Y12="C"),0,IF(AND(#REF!="1",Y12="D"),0,IF(AND(#REF!="2",Y12="A"),1.2,IF(AND(#REF!="2",Y12="B"),1,IF(AND(#REF!="2",Y12="C"),0.1,IF(AND(#REF!="2",Y12="D"),0,IF(AND(#REF!="3",Y12="A"),1.3,IF(AND(#REF!="3",Y12="B"),1.1,IF(AND(#REF!="3",Y12="C"),0.3,IF(AND(#REF!="3",Y12="D"),0,IF(AND(#REF!="4",Y12="A"),1.5,IF(AND(#REF!="4",Y12="B"),1.3,IF(AND(#REF!="4",Y12="C"),0.4,IF(AND(#REF!="4",Y12="D"),0,IF(AND(#REF!="5",Y12="A"),1.6,IF(AND(#REF!="5",Y12="B"),1.4,IF(AND(#REF!="5",Y12="C"),0.5,IF(AND(#REF!="5",Y12="D"),0,)))))))))))))))))))) -> #REF! | AB12: =_xlfn.IFNA(INDEX(Data!$H$66:$L$69,MATCH('DL 1'!D13,Data!$G$66:$G$69,1),MATCH(CONVERT!#REF!,Data!$H$65:$L$65,1)),0) -> 0 | AC12: =_xlfn.IFNA(INDEX(Data!$H$66:$L$69,MATCH('DL 1'!D4,Data!$G$66:$G$69,1),MATCH(CONVERT!#REF!,Data!$H$65:$L$65,1)),0) -> 0 | AD12: =SUM(AC12) -> 0 | AE12: ='DL 1'!F13 -> Y | AF12: =IFERROR(VLOOKUP(Y12,Data!$G$65:$K$79,4,0),"") -> 1.3 | AG12: =#REF! -> #REF! | AK12: =IF(G12<1,0,IF(G12<12000000,1,IF(AND(G12>=12000000,G12<25000000),2,IF(AND(G12>=25000000,G12<50000000),3,IF(AND(G12>=50000000),4,))))) -> 1 | AL12: =IF(AND(S12<12,Y12="A"),0.9,IF(AND(S12<12,Y12="B"),0.7,IF(AND(S12<12,Y12="C"),0,IF(AND(S12<12,Y12="D"),0,IF(AND(S12>=12,S12<15,Y12="A"),1.2,IF(AND(S12>=12,S12<15,Y12="B"),1,IF(AND(S12>=12,S12<15,Y12="C"),0.1,IF(AND(S12>=12,S12<15,Y12="D"),0,IF(AND(S12>=15,S12<18,Y12="A"),1.3,IF(AND(S12>=15,S12<18,Y12="B"),1.1,IF(AND(S12>=15,S12<18,Y12="C"),0.3,IF(AND(S12>=15,S12<18,Y12="D"),0,IF(AND(S12>=18,S12<24,Y12="A"),1.5,IF(AND(S12>=18,S12<24,Y12="B"),1.3,IF(AND(S12>=18,S12<24,Y12="C"),0.4,IF(AND(S12>=18,S12<24,Y12="D"),0,IF(AND(S12>=24,Y12="A"),1.6,IF(AND(S12>=24,Y12="B"),1.4,IF(AND(S12>=24,Y12="C"),0.5,IF(AND(S12>=24,Y12="D"),0,)))))))))))))))))))) -> 1.5 | AM12: =X12*(AL12/100) -> 135000 | AN12: =Q12 -> 20000
